<robot name="megabot">
    <link name="chassis">
        <visual>
            <origin xyz="0 0 0" rpy="0 -0 0"/>
            <geometry>
                <mesh filename="package://chassis.stl"/>
            </geometry>
            <material name="chassis_material">
                <color rgba="0.615686 0.811765 0.929412 1.0"/>
            </material>
        </visual>
        <collision>
            <origin xyz="0 0 0" rpy="0 -0 0"/>
            <geometry>
                <mesh filename="package://chassis.stl"/>
            </geometry>
            <material name="chassis_material">
                <color rgba="0.615686 0.811765 0.929412 1.0"/>
            </material>
        </collision>
        <inertial>
            <origin xyz="-1.94588e-16 -0.525 0.000101117" rpy="0 0 0"/>
            <mass value="30.1813"/>
            <inertia ixx="4.96773" ixy="-1.48273e-14" ixz="-1.67905e-16" iyy="4.97348" iyz="-2.66943e-16" izz="9.9183"/>
        </inertial>
    </link>

    <link name="hanche">
        <visual>
            <origin xyz="-0.065 0 0" rpy="-3.14159 -1.82999e-32 6.15117e-17"/>
            <geometry>
                <mesh filename="package://hanche.stl"/>
            </geometry>
            <material name="hanche_material">
                <color rgba="0.647059 0.647059 0.647059 1.0"/>
            </material>
        </visual>
        <collision>
            <origin xyz="-0.065 0 0" rpy="-3.14159 -1.82999e-32 6.15117e-17"/>
            <geometry>
                <mesh filename="package://hanche.stl"/>
            </geometry>
            <material name="hanche_material">
                <color rgba="0.647059 0.647059 0.647059 1.0"/>
            </material>
        </collision>
        <inertial>
            <origin xyz="-0.0375418 1.28638e-17 -0.0164898" rpy="0 0 0"/>
            <mass value="6.76832"/>
            <inertia ixx="0.0155143" ixy="-1.56271e-17" ixz="-0.0226558" iyy="0.237688" iyz="1.46984e-18"
                     izz="0.241914"/>
        </inertial>
    </link>

    <link name="cuisse">
        <visual>
            <origin xyz="-1.11022e-16 -0.2425 0.03" rpy="1.5708 1.5783e-17 -9.97101e-18"/>
            <geometry>
                <mesh filename="package://cuisse.stl"/>
            </geometry>
            <material name="cuisse_material">
                <color rgba="0.231373 0.380392 0.705882 1.0"/>
            </material>
        </visual>
        <collision>
            <origin xyz="-1.11022e-16 -0.2425 0.03" rpy="1.5708 1.5783e-17 -9.97101e-18"/>
            <geometry>
                <mesh filename="package://cuisse.stl"/>
            </geometry>
            <material name="cuisse_material">
                <color rgba="0.231373 0.380392 0.705882 1.0"/>
            </material>
        </collision>
        <inertial>
            <origin xyz="0.00641397 -0.245927 -0.02" rpy="0 0 0"/>
            <mass value="1.51643"/>
            <inertia ixx="0.0342844" ixy="8.38913e-05" ixz="-4.96328e-11" iyy="0.00340326" iyz="-2.43061e-11"
                     izz="0.0314625"/>
        </inertial>
    </link>

    <link name="tibia">
        <visual>
            <origin xyz="-0.375 1.11022e-16 -1.11022e-16" rpy="1.5708 -5.91512e-17 -3.9443e-31"/>
            <geometry>
                <mesh filename="package://tibia.stl"/>
            </geometry>
            <material name="tibia_material">
                <color rgba="0.917647 0.917647 0.917647 1.0"/>
            </material>
        </visual>
        <collision>
            <origin xyz="-0.375 1.11022e-16 -1.11022e-16" rpy="1.5708 -5.91512e-17 -3.9443e-31"/>
            <geometry>
                <mesh filename="package://tibia.stl"/>
            </geometry>
            <material name="tibia_material">
                <color rgba="0.917647 0.917647 0.917647 1.0"/>
            </material>
        </collision>
        <inertial>
            <origin xyz="-0.374888 1.11164e-16 -0.02" rpy="0 0 0"/>
            <mass value="3.57021"/>
            <inertia ixx="0.00264577" ixy="1.12995e-17" ixz="7.84655e-32" iyy="0.195451" iyz="-5.80252e-32"
                     izz="0.196288"/>
        </inertial>
    </link>

    <link name="pied">
        <visual>
            <origin xyz="-2.22045e-16 0.3475 0.07" rpy="1.5708 1.84297e-17 0"/>
            <geometry>
                <mesh filename="package://pied.stl"/>
            </geometry>
            <material name="pied_material">
                <color rgba="0.231373 0.380392 0.705882 1.0"/>
            </material>
        </visual>
        <collision>
            <origin xyz="-2.22045e-16 0.3475 0.07" rpy="1.5708 1.84297e-17 0"/>
            <geometry>
                <mesh filename="package://pied.stl"/>
            </geometry>
            <material name="pied_material">
                <color rgba="0.231373 0.380392 0.705882 1.0"/>
            </material>
        </collision>
        <inertial>
            <origin xyz="0.00674789 0.371096 0.02" rpy="0 0 0"/>
            <mass value="1.90862"/>
            <inertia ixx="0.14346" ixy="-0.000281054" ixz="1.66321e-08" iyy="0.00295345" iyz="1.76799e-09"
                     izz="0.141209"/>
        </inertial>
    </link>

    <link name="vérin_m">
        <visual>
            <origin xyz="-0.3275 -0.0355 -1.11022e-16" rpy="1.5708 1.5708 0"/>
            <geometry>
                <mesh filename="package://vérin_m.stl"/>
            </geometry>
            <material name="vérin_m_material">
                <color rgba="0.972549 0.529412 0.00392157 1.0"/>
            </material>
        </visual>
        <collision>
            <origin xyz="-0.3275 -0.0355 -1.11022e-16" rpy="1.5708 1.5708 0"/>
            <geometry>
                <mesh filename="package://vérin_m.stl"/>
            </geometry>
            <material name="vérin_m_material">
                <color rgba="0.972549 0.529412 0.00392157 1.0"/>
            </material>
        </collision>
        <inertial>
            <origin xyz="-0.18637 4.92938e-09 -4.07398e-10" rpy="0 0 0"/>
            <mass value="1.92684"/>
            <inertia ixx="0.023605" ixy="3.04855e-11" ixz="1.08751e-09" iyy="0.0236064" iyz="1.74386e-10"
                     izz="0.00019771"/>
        </inertial>
    </link>

    <link name="vérin_f">
        <visual>
            <origin xyz="1.11022e-16 -0.0355 0.05" rpy="1.5708 -5.58312e-17 -1.12912e-18"/>
            <geometry>
                <mesh filename="package://vérin_f.stl"/>
            </geometry>
            <material name="vérin_f_material">
                <color rgba="0.768627 0.886275 0.952941 1.0"/>
            </material>
        </visual>
        <collision>
            <origin xyz="1.11022e-16 -0.0355 0.05" rpy="1.5708 -5.58312e-17 -1.12912e-18"/>
            <geometry>
                <mesh filename="package://vérin_f.stl"/>
            </geometry>
            <material name="vérin_f_material">
                <color rgba="0.768627 0.886275 0.952941 1.0"/>
            </material>
        </collision>
        <inertial>
            <origin xyz="3.32076e-10 -0.0342983 0.0718149" rpy="0 0 0"/>
            <mass value="13.8405"/>
            <inertia ixx="0.1564" ixy="1.67477e-11" ixz="-4.94005e-10" iyy="0.139129" iyz="-0.0107561" izz="0.0268384"/>
        </inertial>
    </link>

    <link name="connecteur">
        <visual>
            <origin xyz="-2.22045e-16 0 1.11022e-16" rpy="1.5708 1.5708 0"/>
            <geometry>
                <mesh filename="package://connecteur.stl"/>
            </geometry>
            <material name="connecteur_material">
                <color rgba="0.498039 0.498039 0.498039 1.0"/>
            </material>
        </visual>
        <collision>
            <origin xyz="-2.22045e-16 0 1.11022e-16" rpy="1.5708 1.5708 0"/>
            <geometry>
                <mesh filename="package://connecteur.stl"/>
            </geometry>
            <material name="connecteur_material">
                <color rgba="0.498039 0.498039 0.498039 1.0"/>
            </material>
        </collision>
        <inertial>
            <origin xyz="-2.22045e-16 1.16945e-19 1.08831e-16" rpy="0 0 0"/>
            <mass value="0.00475914"/>
            <inertia ixx="6.77384e-07" ixy="3.01871e-23" ixz="1.52717e-23" iyy="8.56644e-08" iyz="1.29384e-23"
                     izz="6.77384e-07"/>
        </inertial>
    </link>

    <joint name="co_07" type="fixed">
        <origin xyz="-3.33067e-16 3.33067e-16 -0.068" rpy="7.31865e-16 1.5708 0"/>
        <parent link="vérin_f"/>
        <child link="connecteur"/>
        <axis xyz="0 0 1"/>
        <limit effort="1" velocity="20"/>
        <joint_properties friction="0.0"/>
    </joint>

    <joint name="0v2" type="prismatic">
        <origin xyz="-0.382 1.11022e-16 2.22045e-16" rpy="-3.14159 -1.5708 0"/>
        <parent link="vérin_m"/>
        <child link="vérin_f"/>
        <axis xyz="0 0 1"/>
        <limit effort="1" velocity="20" lower="-0.2045" upper="-0.0045"/>
        <joint_properties friction="0.0"/>
    </joint>

    <joint name="07" type="revolute">
        <origin xyz="-2.22045e-16 0.505 0.02" rpy="3.14159 -2.26036e-15 0.354305"/>
        <parent link="pied"/>
        <child link="vérin_m"/>
        <axis xyz="0 0 1"/>
        <limit effort="1" velocity="20"/>
        <joint_properties friction="0.0"/>
    </joint>

    <joint name="03" type="revolute">
        <origin xyz="-0.75 2.22045e-16 1.11022e-16" rpy="3.14159 -7.51254e-16 3.14159"/>
        <parent link="tibia"/>
        <child link="pied"/>
        <axis xyz="0 0 1"/>
        <limit effort="1" velocity="20"/>
        <joint_properties friction="0.0"/>
    </joint>

    <link name="support_v2">
        <visual>
            <origin xyz="0 0.3475 0.07" rpy="1.5708 2.86474e-17 2.6782e-32"/>
            <geometry>
                <mesh filename="package://support_v2.stl"/>
            </geometry>
            <material name="support_v2_material">
                <color rgba="0.231373 0.380392 0.705882 1.0"/>
            </material>
        </visual>
        <collision>
            <origin xyz="0 0.3475 0.07" rpy="1.5708 2.86474e-17 2.6782e-32"/>
            <geometry>
                <mesh filename="package://support_v2.stl"/>
            </geometry>
            <material name="support_v2_material">
                <color rgba="0.231373 0.380392 0.705882 1.0"/>
            </material>
        </collision>
        <inertial>
            <origin xyz="0.00543544 0.291712 0.0198471" rpy="0 0 0"/>
            <mass value="1.58654"/>
            <inertia ixx="0.0561792" ixy="-6.54178e-05" ixz="-4.14017e-06" iyy="0.00372126" iyz="8.07606e-06"
                     izz="0.0530513"/>
        </inertial>
    </link>

    <link name="connecteur_2">
        <visual>
            <origin xyz="0 1.38778e-17 -0.02" rpy="-1.5708 -1.5708 0"/>
            <geometry>
                <mesh filename="package://connecteur.stl"/>
            </geometry>
            <material name="connecteur_material">
                <color rgba="0.498039 0.498039 0.498039 1.0"/>
            </material>
        </visual>
        <collision>
            <origin xyz="0 1.38778e-17 -0.02" rpy="-1.5708 -1.5708 0"/>
            <geometry>
                <mesh filename="package://connecteur.stl"/>
            </geometry>
            <material name="connecteur_material">
                <color rgba="0.498039 0.498039 0.498039 1.0"/>
            </material>
        </collision>
        <inertial>
            <origin xyz="-9.87803e-35 1.37608e-17 -0.02" rpy="0 0 0"/>
            <mass value="0.00475914"/>
            <inertia ixx="6.77384e-07" ixy="1.55429e-23" ixz="2.56625e-37" iyy="8.56644e-08" iyz="2.36324e-38"
                     izz="6.77384e-07"/>
        </inertial>
    </link>

    <joint name="co_01" type="fixed">
        <origin xyz="-2.22045e-16 0.59 1.11022e-16" rpy="-3.14159 2.86474e-17 2.6782e-32"/>
        <parent link="support_v2"/>
        <child link="connecteur_2"/>
        <axis xyz="0 0 1"/>
        <limit effort="1" velocity="20"/>
        <joint_properties friction="0.0"/>
    </joint>

    <link name="connecteur_3">
        <visual>
            <origin xyz="-2.22045e-16 0 0" rpy="1.5708 1.5708 0"/>
            <geometry>
                <mesh filename="package://connecteur.stl"/>
            </geometry>
            <material name="connecteur_material">
                <color rgba="0.498039 0.498039 0.498039 1.0"/>
            </material>
        </visual>
        <collision>
            <origin xyz="-2.22045e-16 0 0" rpy="1.5708 1.5708 0"/>
            <geometry>
                <mesh filename="package://connecteur.stl"/>
            </geometry>
            <material name="connecteur_material">
                <color rgba="0.498039 0.498039 0.498039 1.0"/>
            </material>
        </collision>
        <inertial>
            <origin xyz="-2.22045e-16 1.16945e-19 -2.19085e-18" rpy="0 0 0"/>
            <mass value="0.00475914"/>
            <inertia ixx="6.77384e-07" ixy="1.55429e-23" ixz="2.56625e-37" iyy="8.56644e-08" iyz="2.36324e-38"
                     izz="6.77384e-07"/>
        </inertial>
    </link>

    <joint name="co_06" type="fixed">
        <origin xyz="-2.22045e-16 0.1975 0.02" rpy="2.5208e-31 2.86474e-17 2.6782e-32"/>
        <parent link="support_v2"/>
        <child link="connecteur_3"/>
        <axis xyz="0 0 1"/>
        <limit effort="1" velocity="20"/>
        <joint_properties friction="0.0"/>
    </joint>

    <joint name="04" type="revolute">
        <origin xyz="-0.45 0 -0.04" rpy="-8.53089e-16 8.39725e-16 4.43242e-16"/>
        <parent link="tibia"/>
        <child link="support_v2"/>
        <axis xyz="0 0 1"/>
        <limit effort="1" velocity="20"/>
        <joint_properties friction="0.0"/>
    </joint>

    <joint name="02" type="revolute">
        <origin xyz="-3.33067e-16 -0.49 -2.22045e-16" rpy="-2.21069e-16 6.42827e-16 0.354305"/>
        <parent link="cuisse"/>
        <child link="tibia"/>
        <axis xyz="0 0 1"/>
        <limit effort="1" velocity="20"/>
        <joint_properties friction="0.0"/>
    </joint>

    <link name="vérin_m_2">
        <visual>
            <origin xyz="-0.3275 -0.0355 0" rpy="1.5708 1.5708 0"/>
            <geometry>
                <mesh filename="package://vérin_m.stl"/>
            </geometry>
            <material name="vérin_m_material">
                <color rgba="0.972549 0.529412 0.00392157 1.0"/>
            </material>
        </visual>
        <collision>
            <origin xyz="-0.3275 -0.0355 0" rpy="1.5708 1.5708 0"/>
            <geometry>
                <mesh filename="package://vérin_m.stl"/>
            </geometry>
            <material name="vérin_m_material">
                <color rgba="0.972549 0.529412 0.00392157 1.0"/>
            </material>
        </collision>
        <inertial>
            <origin xyz="-0.18637 4.92938e-09 -4.07398e-10" rpy="0 0 0"/>
            <mass value="1.92684"/>
            <inertia ixx="0.023605" ixy="3.04855e-11" ixz="1.08751e-09" iyy="0.0236064" iyz="1.74386e-10"
                     izz="0.00019771"/>
        </inertial>
    </link>

    <link name="vérin_f_2">
        <visual>
            <origin xyz="0 -0.0355 0.05" rpy="1.5708 -4.54884e-17 2.29036e-17"/>
            <geometry>
                <mesh filename="package://vérin_f.stl"/>
            </geometry>
            <material name="vérin_f_material">
                <color rgba="0.768627 0.886275 0.952941 1.0"/>
            </material>
        </visual>
        <collision>
            <origin xyz="0 -0.0355 0.05" rpy="1.5708 -4.54884e-17 2.29036e-17"/>
            <geometry>
                <mesh filename="package://vérin_f.stl"/>
            </geometry>
            <material name="vérin_f_material">
                <color rgba="0.768627 0.886275 0.952941 1.0"/>
            </material>
        </collision>
        <inertial>
            <origin xyz="3.32076e-10 -0.0342983 0.0718149" rpy="0 0 0"/>
            <mass value="13.8405"/>
            <inertia ixx="0.1564" ixy="1.67477e-11" ixz="-4.94005e-10" iyy="0.139129" iyz="-0.0107561" izz="0.0268384"/>
        </inertial>
    </link>

    <link name="connecteur_4">
        <visual>
            <origin xyz="2.22045e-16 -1.11022e-16 0" rpy="1.5708 1.5708 0"/>
            <geometry>
                <mesh filename="package://connecteur.stl"/>
            </geometry>
            <material name="connecteur_material">
                <color rgba="0.498039 0.498039 0.498039 1.0"/>
            </material>
        </visual>
        <collision>
            <origin xyz="2.22045e-16 -1.11022e-16 0" rpy="1.5708 1.5708 0"/>
            <geometry>
                <mesh filename="package://connecteur.stl"/>
            </geometry>
            <material name="connecteur_material">
                <color rgba="0.498039 0.498039 0.498039 1.0"/>
            </material>
        </collision>
        <inertial>
            <origin xyz="2.22045e-16 -1.10905e-16 -2.19085e-18" rpy="0 0 0"/>
            <mass value="0.00475914"/>
            <inertia ixx="6.77384e-07" ixy="5.67921e-24" ixz="-2.06984e-23" iyy="8.56644e-08" iyz="1.7349e-24"
                     izz="6.77384e-07"/>
        </inertial>
    </link>

    <joint name="co_05" type="fixed">
        <origin xyz="-1.11022e-16 0 -0.068" rpy="4.41331e-16 -1.5708 0"/>
        <parent link="vérin_f_2"/>
        <child link="connecteur_4"/>
        <axis xyz="0 0 1"/>
        <limit effort="1" velocity="20"/>
        <joint_properties friction="0.0"/>
    </joint>

    <joint name="0v1" type="prismatic">
        <origin xyz="-0.382 -2.22045e-16 0" rpy="3.44509e-17 1.5708 0"/>
        <parent link="vérin_m_2"/>
        <child link="vérin_f_2"/>
        <axis xyz="0 0 1"/>
        <limit effort="1" velocity="20" lower="-0.2045" upper="-0.0045"/>
        <joint_properties friction="0.0"/>
    </joint>

    <joint name="06" type="revolute">
        <origin xyz="-0.013 -0.384 -0.02" rpy="-2.20387e-17 1.5783e-17 -9.97101e-18"/>
        <parent link="cuisse"/>
        <child link="vérin_m_2"/>
        <axis xyz="0 0 1"/>
        <limit effort="1" velocity="20"/>
        <joint_properties friction="0.0"/>
    </joint>

    <joint name="01" type="revolute">
        <origin xyz="0.125 -0.02 -0.04" rpy="1.5708 0.354305 -3.04427e-15"/>
        <parent link="hanche"/>
        <child link="cuisse"/>
        <axis xyz="0 0 1"/>
        <limit effort="1" velocity="20"/>
        <joint_properties friction="0.0"/>
    </joint>

    <link name="vérin_m_3">
        <visual>
            <origin xyz="-0.3275 -0.0355 -7.57941e-18" rpy="1.5708 1.5708 0"/>
            <geometry>
                <mesh filename="package://vérin_m.stl"/>
            </geometry>
            <material name="vérin_m_material">
                <color rgba="0.972549 0.529412 0.00392157 1.0"/>
            </material>
        </visual>
        <collision>
            <origin xyz="-0.3275 -0.0355 -7.57941e-18" rpy="1.5708 1.5708 0"/>
            <geometry>
                <mesh filename="package://vérin_m.stl"/>
            </geometry>
            <material name="vérin_m_material">
                <color rgba="0.972549 0.529412 0.00392157 1.0"/>
            </material>
        </collision>
        <inertial>
            <origin xyz="-0.18637 4.92938e-09 -4.07398e-10" rpy="0 0 0"/>
            <mass value="1.92684"/>
            <inertia ixx="0.023605" ixy="3.04855e-11" ixz="1.08751e-09" iyy="0.0236064" iyz="1.74386e-10"
                     izz="0.00019771"/>
        </inertial>
    </link>

    <link name="vérin_f_3">
        <visual>
            <origin xyz="0 -0.0355 0.05" rpy="1.5708 1.05262e-33 -1.43424e-34"/>
            <geometry>
                <mesh filename="package://vérin_f.stl"/>
            </geometry>
            <material name="vérin_f_material">
                <color rgba="0.768627 0.886275 0.952941 1.0"/>
            </material>
        </visual>
        <collision>
            <origin xyz="0 -0.0355 0.05" rpy="1.5708 1.05262e-33 -1.43424e-34"/>
            <geometry>
                <mesh filename="package://vérin_f.stl"/>
            </geometry>
            <material name="vérin_f_material">
                <color rgba="0.768627 0.886275 0.952941 1.0"/>
            </material>
        </collision>
        <inertial>
            <origin xyz="3.32076e-10 -0.0342983 0.0718149" rpy="0 0 0"/>
            <mass value="13.8405"/>
            <inertia ixx="0.1564" ixy="1.67477e-11" ixz="-4.94005e-10" iyy="0.139129" iyz="-0.0107561" izz="0.0268384"/>
        </inertial>
    </link>

    <link name="connecteur_5">
        <visual>
            <origin xyz="0 0 1.73472e-18" rpy="1.5708 1.5708 0"/>
            <geometry>
                <mesh filename="package://connecteur.stl"/>
            </geometry>
            <material name="connecteur_material">
                <color rgba="0.498039 0.498039 0.498039 1.0"/>
            </material>
        </visual>
        <collision>
            <origin xyz="0 0 1.73472e-18" rpy="1.5708 1.5708 0"/>
            <geometry>
                <mesh filename="package://connecteur.stl"/>
            </geometry>
            <material name="connecteur_material">
                <color rgba="0.498039 0.498039 0.498039 1.0"/>
            </material>
        </collision>
        <inertial>
            <origin xyz="7.857e-51 1.16945e-19 -4.56127e-19" rpy="0 0 0"/>
            <mass value="0.00475914"/>
            <inertia ixx="6.77384e-07" ixy="-1.33677e-39" ixz="-1.21282e-39" iyy="8.56644e-08" iyz="-7.81227e-39"
                     izz="6.77384e-07"/>
        </inertial>
    </link>

    <joint name="co_03" type="fixed">
        <origin xyz="-2.72047e-18 0 -0.068" rpy="-3.14159 1.5708 0"/>
        <parent link="vérin_f_3"/>
        <child link="connecteur_5"/>
        <axis xyz="0 0 1"/>
        <limit effort="1" velocity="20"/>
        <joint_properties friction="0.0"/>
    </joint>

    <joint name="0v3" type="prismatic">
        <origin xyz="-0.505143 1.88738e-15 -1.89009e-17" rpy="7.57727e-15 1.5708 0"/>
        <parent link="vérin_m_3"/>
        <child link="vérin_f_3"/>
        <axis xyz="0 0 1"/>
        <limit effort="1" velocity="20" lower="-0.2045" upper="-0.0045"/>
        <joint_properties friction="0.0"/>
    </joint>

    <joint name="05" type="revolute">
        <origin xyz="0.275 -8.88178e-16 0.025" rpy="-3.30729e-16 -1.08068e-16 2.49723"/>
        <parent link="hanche"/>
        <child link="vérin_m_3"/>
        <axis xyz="0 0 1"/>
        <limit effort="1" velocity="20" lower="0" upper="0"/>
        <joint_properties friction="0.0"/>
    </joint>

    <link name="connecteur_6">
        <visual>
            <origin xyz="0 -1.38778e-17 0.02" rpy="1.5708 1.5708 0"/>
            <geometry>
                <mesh filename="package://connecteur.stl"/>
            </geometry>
            <material name="connecteur_material">
                <color rgba="0.498039 0.498039 0.498039 1.0"/>
            </material>
        </visual>
        <collision>
            <origin xyz="0 -1.38778e-17 0.02" rpy="1.5708 1.5708 0"/>
            <geometry>
                <mesh filename="package://connecteur.stl"/>
            </geometry>
            <material name="connecteur_material">
                <color rgba="0.498039 0.498039 0.498039 1.0"/>
            </material>
        </collision>
        <inertial>
            <origin xyz="-9.86283e-35 -1.37608e-17 0.02" rpy="0 0 0"/>
            <mass value="0.00475914"/>
            <inertia ixx="6.77384e-07" ixy="-6.94444e-24" ixz="-2.59175e-38" iyy="8.56644e-08" iyz="1.50912e-38"
                     izz="6.77384e-07"/>
        </inertial>
    </link>

    <joint name="co_00" type="fixed">
        <origin xyz="-0.125 -0.02 -0.04" rpy="-1.5708 -2.95373e-28 -1.29302e-15"/>
        <parent link="hanche"/>
        <child link="connecteur_6"/>
        <axis xyz="0 0 1"/>
        <limit effort="1" velocity="20"/>
        <joint_properties friction="0.0"/>
    </joint>

    <link name="connecteur_7">
        <visual>
            <origin xyz="-2.22045e-16 0 0" rpy="1.5708 1.5708 0"/>
            <geometry>
                <mesh filename="package://connecteur.stl"/>
            </geometry>
            <material name="connecteur_material">
                <color rgba="0.498039 0.498039 0.498039 1.0"/>
            </material>
        </visual>
        <collision>
            <origin xyz="-2.22045e-16 0 0" rpy="1.5708 1.5708 0"/>
            <geometry>
                <mesh filename="package://connecteur.stl"/>
            </geometry>
            <material name="connecteur_material">
                <color rgba="0.498039 0.498039 0.498039 1.0"/>
            </material>
        </collision>
        <inertial>
            <origin xyz="-2.22045e-16 1.16945e-19 -2.19085e-18" rpy="0 0 0"/>
            <mass value="0.00475914"/>
            <inertia ixx="6.77384e-07" ixy="4.72246e-23" ixz="-9.21867e-39" iyy="8.56644e-08" iyz="-6.69294e-39"
                     izz="6.77384e-07"/>
        </inertial>
    </link>

    <joint name="co_04" type="fixed">
        <origin xyz="-0.41 0 -0.095" rpy="1.5708 -1.82999e-32 6.15117e-17"/>
        <parent link="hanche"/>
        <child link="connecteur_7"/>
        <axis xyz="0 0 1"/>
        <limit effort="1" velocity="20"/>
        <joint_properties friction="0.0"/>
    </joint>

    <joint name="00" type="revolute">
        <origin xyz="0.5 -1.025 0.025" rpy="3.14159 1.5982e-17 2.49723"/>
        <parent link="chassis"/>
        <child link="hanche"/>
        <axis xyz="0 0 1"/>
        <limit effort="1" velocity="20"/>
        <joint_properties friction="0.0"/>
    </joint>

    <link name="hanche_2">
        <visual>
            <origin xyz="-0.065 0 0" rpy="3.14159 -8.96831e-43 9.93039e-18"/>
            <geometry>
                <mesh filename="package://hanche.stl"/>
            </geometry>
            <material name="hanche_material">
                <color rgba="0.647059 0.647059 0.647059 1.0"/>
            </material>
        </visual>
        <collision>
            <origin xyz="-0.065 0 0" rpy="3.14159 -8.96831e-43 9.93039e-18"/>
            <geometry>
                <mesh filename="package://hanche.stl"/>
            </geometry>
            <material name="hanche_material">
                <color rgba="0.647059 0.647059 0.647059 1.0"/>
            </material>
        </collision>
        <inertial>
            <origin xyz="-0.0375418 1.14475e-17 -0.0164898" rpy="0 0 0"/>
            <mass value="6.76832"/>
            <inertia ixx="0.0155143" ixy="-3.36284e-18" ixz="-0.0226558" iyy="0.237688" iyz="1.46397e-18"
                     izz="0.241914"/>
        </inertial>
    </link>

    <link name="cuisse_2">
        <visual>
            <origin xyz="1.11022e-16 -0.2425 0.03" rpy="1.5708 -2.0439e-17 -3.55671e-18"/>
            <geometry>
                <mesh filename="package://cuisse.stl"/>
            </geometry>
            <material name="cuisse_material">
                <color rgba="0.231373 0.380392 0.705882 1.0"/>
            </material>
        </visual>
        <collision>
            <origin xyz="1.11022e-16 -0.2425 0.03" rpy="1.5708 -2.0439e-17 -3.55671e-18"/>
            <geometry>
                <mesh filename="package://cuisse.stl"/>
            </geometry>
            <material name="cuisse_material">
                <color rgba="0.231373 0.380392 0.705882 1.0"/>
            </material>
        </collision>
        <inertial>
            <origin xyz="0.00641397 -0.245927 -0.02" rpy="0 0 0"/>
            <mass value="1.51643"/>
            <inertia ixx="0.0342844" ixy="8.38913e-05" ixz="-4.96328e-11" iyy="0.00340326" iyz="-2.43061e-11"
                     izz="0.0314625"/>
        </inertial>
    </link>

    <link name="tibia_2">
        <visual>
            <origin xyz="-0.375 0 -0.04" rpy="-1.5708 -7.80167e-18 0"/>
            <geometry>
                <mesh filename="package://tibia.stl"/>
            </geometry>
            <material name="tibia_material">
                <color rgba="0.917647 0.917647 0.917647 1.0"/>
            </material>
        </visual>
        <collision>
            <origin xyz="-0.375 0 -0.04" rpy="-1.5708 -7.80167e-18 0"/>
            <geometry>
                <mesh filename="package://tibia.stl"/>
            </geometry>
            <material name="tibia_material">
                <color rgba="0.917647 0.917647 0.917647 1.0"/>
            </material>
        </collision>
        <inertial>
            <origin xyz="-0.374888 -1.41517e-19 -0.02" rpy="0 0 0"/>
            <mass value="3.57021"/>
            <inertia ixx="0.00264577" ixy="-1.48022e-18" ixz="1.38145e-48" iyy="0.195451" iyz="-1.23238e-31"
                     izz="0.196288"/>
        </inertial>
    </link>

    <link name="pied_2">
        <visual>
            <origin xyz="0 0.3475 0.07" rpy="1.5708 -6.48742e-18 6.34434e-31"/>
            <geometry>
                <mesh filename="package://pied.stl"/>
            </geometry>
            <material name="pied_material">
                <color rgba="0.231373 0.380392 0.705882 1.0"/>
            </material>
        </visual>
        <collision>
            <origin xyz="0 0.3475 0.07" rpy="1.5708 -6.48742e-18 6.34434e-31"/>
            <geometry>
                <mesh filename="package://pied.stl"/>
            </geometry>
            <material name="pied_material">
                <color rgba="0.231373 0.380392 0.705882 1.0"/>
            </material>
        </collision>
        <inertial>
            <origin xyz="0.00674789 0.371096 0.02" rpy="0 0 0"/>
            <mass value="1.90862"/>
            <inertia ixx="0.14346" ixy="-0.000281054" ixz="1.66321e-08" iyy="0.00295345" iyz="1.76799e-09"
                     izz="0.141209"/>
        </inertial>
    </link>

    <link name="vérin_m_4">
        <visual>
            <origin xyz="-0.3275 -0.0355 -2.22045e-16" rpy="1.5708 1.5708 0"/>
            <geometry>
                <mesh filename="package://vérin_m.stl"/>
            </geometry>
            <material name="vérin_m_material">
                <color rgba="0.972549 0.529412 0.00392157 1.0"/>
            </material>
        </visual>
        <collision>
            <origin xyz="-0.3275 -0.0355 -2.22045e-16" rpy="1.5708 1.5708 0"/>
            <geometry>
                <mesh filename="package://vérin_m.stl"/>
            </geometry>
            <material name="vérin_m_material">
                <color rgba="0.972549 0.529412 0.00392157 1.0"/>
            </material>
        </collision>
        <inertial>
            <origin xyz="-0.18637 4.92938e-09 -4.07398e-10" rpy="0 0 0"/>
            <mass value="1.92684"/>
            <inertia ixx="0.023605" ixy="3.04855e-11" ixz="1.08751e-09" iyy="0.0236064" iyz="1.74386e-10"
                     izz="0.00019771"/>
        </inertial>
    </link>

    <link name="vérin_f_4">
        <visual>
            <origin xyz="2.77556e-16 -0.0355 0.05" rpy="1.5708 -3.28974e-17 -1.14711e-17"/>
            <geometry>
                <mesh filename="package://vérin_f.stl"/>
            </geometry>
            <material name="vérin_f_material">
                <color rgba="0.768627 0.886275 0.952941 1.0"/>
            </material>
        </visual>
        <collision>
            <origin xyz="2.77556e-16 -0.0355 0.05" rpy="1.5708 -3.28974e-17 -1.14711e-17"/>
            <geometry>
                <mesh filename="package://vérin_f.stl"/>
            </geometry>
            <material name="vérin_f_material">
                <color rgba="0.768627 0.886275 0.952941 1.0"/>
            </material>
        </collision>
        <inertial>
            <origin xyz="3.32077e-10 -0.0342983 0.0718149" rpy="0 0 0"/>
            <mass value="13.8405"/>
            <inertia ixx="0.1564" ixy="1.67477e-11" ixz="-4.94005e-10" iyy="0.139129" iyz="-0.0107561" izz="0.0268384"/>
        </inertial>
    </link>

    <link name="connecteur_8">
        <visual>
            <origin xyz="0 0 0" rpy="1.5708 1.5708 0"/>
            <geometry>
                <mesh filename="package://connecteur.stl"/>
            </geometry>
            <material name="connecteur_material">
                <color rgba="0.498039 0.498039 0.498039 1.0"/>
            </material>
        </visual>
        <collision>
            <origin xyz="0 0 0" rpy="1.5708 1.5708 0"/>
            <geometry>
                <mesh filename="package://connecteur.stl"/>
            </geometry>
            <material name="connecteur_material">
                <color rgba="0.498039 0.498039 0.498039 1.0"/>
            </material>
        </collision>
        <inertial>
            <origin xyz="1.9156e-34 1.16945e-19 -2.19085e-18" rpy="0 0 0"/>
            <mass value="0.00475914"/>
            <inertia ixx="6.77384e-07" ixy="1.02674e-24" ixz="-2.39494e-23" iyy="8.56644e-08" iyz="-3.97603e-23"
                     izz="6.77384e-07"/>
        </inertial>
    </link>

    <joint name="co_17" type="fixed">
        <origin xyz="1.66533e-16 1.11022e-16 -0.068" rpy="1.77933e-16 1.5708 0"/>
        <parent link="vérin_f_4"/>
        <child link="connecteur_8"/>
        <axis xyz="0 0 1"/>
        <limit effort="1" velocity="20"/>
        <joint_properties friction="0.0"/>
    </joint>

    <joint name="1v2" type="prismatic">
        <origin xyz="-0.382 1.11022e-16 -3.55271e-15" rpy="-3.14159 -1.5708 0"/>
        <parent link="vérin_m_4"/>
        <child link="vérin_f_4"/>
        <axis xyz="0 0 1"/>
        <limit effort="1" velocity="20" lower="-0.2045" upper="-0.0045"/>
        <joint_properties friction="0.0"/>
    </joint>

    <joint name="17" type="revolute">
        <origin xyz="0 0.505 0.02" rpy="-3.14159 -8.22573e-15 0.354305"/>
        <parent link="pied_2"/>
        <child link="vérin_m_4"/>
        <axis xyz="0 0 1"/>
        <limit effort="1" velocity="20"/>
        <joint_properties friction="0.0"/>
    </joint>

    <joint name="13" type="revolute">
        <origin xyz="-0.75 0 -0.04" rpy="-8.6533e-16 3.17465e-16 -3.14159"/>
        <parent link="tibia_2"/>
        <child link="pied_2"/>
        <axis xyz="0 0 1"/>
        <limit effort="1" velocity="20"/>
        <joint_properties friction="0.0"/>
    </joint>

    <link name="support_v2_2">
        <visual>
            <origin xyz="0 -0.3475 -0.03" rpy="-1.5708 1.04295e-17 -5.55772e-32"/>
            <geometry>
                <mesh filename="package://support_v2.stl"/>
            </geometry>
            <material name="support_v2_material">
                <color rgba="0.231373 0.380392 0.705882 1.0"/>
            </material>
        </visual>
        <collision>
            <origin xyz="0 -0.3475 -0.03" rpy="-1.5708 1.04295e-17 -5.55772e-32"/>
            <geometry>
                <mesh filename="package://support_v2.stl"/>
            </geometry>
            <material name="support_v2_material">
                <color rgba="0.231373 0.380392 0.705882 1.0"/>
            </material>
        </collision>
        <inertial>
            <origin xyz="0.00543544 -0.291712 0.0201529" rpy="0 0 0"/>
            <mass value="1.58654"/>
            <inertia ixx="0.0561792" ixy="6.54178e-05" ixz="4.14017e-06" iyy="0.00372126" iyz="8.07606e-06"
                     izz="0.0530513"/>
        </inertial>
    </link>

    <link name="connecteur_9">
        <visual>
            <origin xyz="0 1.38778e-17 0.02" rpy="1.5708 1.5708 0"/>
            <geometry>
                <mesh filename="package://connecteur.stl"/>
            </geometry>
            <material name="connecteur_material">
                <color rgba="0.498039 0.498039 0.498039 1.0"/>
            </material>
        </visual>
        <collision>
            <origin xyz="0 1.38778e-17 0.02" rpy="1.5708 1.5708 0"/>
            <geometry>
                <mesh filename="package://connecteur.stl"/>
            </geometry>
            <material name="connecteur_material">
                <color rgba="0.498039 0.498039 0.498039 1.0"/>
            </material>
        </collision>
        <inertial>
            <origin xyz="-9.62258e-35 1.39947e-17 0.02" rpy="0 0 0"/>
            <mass value="0.00475914"/>
            <inertia ixx="6.77384e-07" ixy="3.16825e-23" ixz="2.61456e-37" iyy="8.56644e-08" iyz="2.30219e-38"
                     izz="6.77384e-07"/>
        </inertial>
    </link>

    <joint name="co_11" type="fixed">
        <origin xyz="0 -0.59 -1.11022e-16" rpy="-1.74276e-15 1.20699e-15 -8.44438e-31"/>
        <parent link="support_v2_2"/>
        <child link="connecteur_9"/>
        <axis xyz="0 0 1"/>
        <limit effort="1" velocity="20"/>
        <joint_properties friction="0.0"/>
    </joint>

    <link name="connecteur_10">
        <visual>
            <origin xyz="2.22045e-16 0 -1.11022e-16" rpy="1.5708 1.5708 0"/>
            <geometry>
                <mesh filename="package://connecteur.stl"/>
            </geometry>
            <material name="connecteur_material">
                <color rgba="0.498039 0.498039 0.498039 1.0"/>
            </material>
        </visual>
        <collision>
            <origin xyz="2.22045e-16 0 -1.11022e-16" rpy="1.5708 1.5708 0"/>
            <geometry>
                <mesh filename="package://connecteur.stl"/>
            </geometry>
            <material name="connecteur_material">
                <color rgba="0.498039 0.498039 0.498039 1.0"/>
            </material>
        </collision>
        <inertial>
            <origin xyz="2.22045e-16 1.16945e-19 -1.13213e-16" rpy="0 0 0"/>
            <mass value="0.00475914"/>
            <inertia ixx="6.77384e-07" ixy="-1.40522e-23" ixz="1.70063e-37" iyy="8.56644e-08" iyz="-1.78382e-39"
                     izz="6.77384e-07"/>
        </inertial>
    </link>

    <joint name="co_16" type="fixed">
        <origin xyz="0 -0.1975 0.02" rpy="-3.14159 1.04295e-17 -5.55772e-32"/>
        <parent link="support_v2_2"/>
        <child link="connecteur_10"/>
        <axis xyz="0 0 1"/>
        <limit effort="1" velocity="20"/>
        <joint_properties friction="0.0"/>
    </joint>

    <joint name="14" type="revolute">
        <origin xyz="-0.45 -6.88338e-15 -0.04" rpy="-1.16184e-15 -9.85516e-16 1.36364e-14"/>
        <parent link="tibia_2"/>
        <child link="support_v2_2"/>
        <axis xyz="0 0 1"/>
        <limit effort="1" velocity="20"/>
        <joint_properties friction="0.0"/>
    </joint>

    <joint name="12" type="revolute">
        <origin xyz="1.33227e-15 -0.49 -0.04" rpy="3.14159 -2.14867e-15 0.354305"/>
        <parent link="cuisse_2"/>
        <child link="tibia_2"/>
        <axis xyz="0 0 1"/>
        <limit effort="1" velocity="20"/>
        <joint_properties friction="0.0"/>
    </joint>

    <link name="vérin_m_5">
        <visual>
            <origin xyz="-0.3275 -0.0355 -5.55112e-17" rpy="1.5708 1.5708 0"/>
            <geometry>
                <mesh filename="package://vérin_m.stl"/>
            </geometry>
            <material name="vérin_m_material">
                <color rgba="0.972549 0.529412 0.00392157 1.0"/>
            </material>
        </visual>
        <collision>
            <origin xyz="-0.3275 -0.0355 -5.55112e-17" rpy="1.5708 1.5708 0"/>
            <geometry>
                <mesh filename="package://vérin_m.stl"/>
            </geometry>
            <material name="vérin_m_material">
                <color rgba="0.972549 0.529412 0.00392157 1.0"/>
            </material>
        </collision>
        <inertial>
            <origin xyz="-0.18637 4.92938e-09 -4.07398e-10" rpy="0 0 0"/>
            <mass value="1.92684"/>
            <inertia ixx="0.023605" ixy="3.04855e-11" ixz="1.08751e-09" iyy="0.0236064" iyz="1.74386e-10"
                     izz="0.00019771"/>
        </inertial>
    </link>

    <link name="vérin_f_5">
        <visual>
            <origin xyz="1.11022e-16 -0.0355 0.05" rpy="1.5708 -1.89056e-17 1.39775e-17"/>
            <geometry>
                <mesh filename="package://vérin_f.stl"/>
            </geometry>
            <material name="vérin_f_material">
                <color rgba="0.768627 0.886275 0.952941 1.0"/>
            </material>
        </visual>
        <collision>
            <origin xyz="1.11022e-16 -0.0355 0.05" rpy="1.5708 -1.89056e-17 1.39775e-17"/>
            <geometry>
                <mesh filename="package://vérin_f.stl"/>
            </geometry>
            <material name="vérin_f_material">
                <color rgba="0.768627 0.886275 0.952941 1.0"/>
            </material>
        </collision>
        <inertial>
            <origin xyz="3.32076e-10 -0.0342983 0.0718149" rpy="0 0 0"/>
            <mass value="13.8405"/>
            <inertia ixx="0.1564" ixy="1.67477e-11" ixz="-4.94005e-10" iyy="0.139129" iyz="-0.0107561" izz="0.0268384"/>
        </inertial>
    </link>

    <link name="connecteur_11">
        <visual>
            <origin xyz="-2.22045e-16 1.11022e-16 0" rpy="1.5708 1.5708 0"/>
            <geometry>
                <mesh filename="package://connecteur.stl"/>
            </geometry>
            <material name="connecteur_material">
                <color rgba="0.498039 0.498039 0.498039 1.0"/>
            </material>
        </visual>
        <collision>
            <origin xyz="-2.22045e-16 1.11022e-16 0" rpy="1.5708 1.5708 0"/>
            <geometry>
                <mesh filename="package://connecteur.stl"/>
            </geometry>
            <material name="connecteur_material">
                <color rgba="0.498039 0.498039 0.498039 1.0"/>
            </material>
        </collision>
        <inertial>
            <origin xyz="-2.22045e-16 1.11139e-16 -2.19085e-18" rpy="0 0 0"/>
            <mass value="0.00475914"/>
            <inertia ixx="6.77384e-07" ixy="2.18019e-23" ixz="-6.00578e-24" iyy="8.56644e-08" iyz="-2.7012e-23"
                     izz="6.77384e-07"/>
        </inertial>
    </link>

    <joint name="co_15" type="fixed">
        <origin xyz="0 -1.11022e-16 -0.068" rpy="-2.3799e-16 -1.5708 0"/>
        <parent link="vérin_f_5"/>
        <child link="connecteur_11"/>
        <axis xyz="0 0 1"/>
        <limit effort="1" velocity="20"/>
        <joint_properties friction="0.0"/>
    </joint>

    <joint name="1v1" type="prismatic">
        <origin xyz="-0.382 -1.11022e-16 0" rpy="2.95496e-15 1.5708 0"/>
        <parent link="vérin_m_5"/>
        <child link="vérin_f_5"/>
        <axis xyz="0 0 1"/>
        <limit effort="1" velocity="20" lower="-0.2045" upper="-0.0045"/>
        <joint_properties friction="0.0"/>
    </joint>

    <joint name="16" type="revolute">
        <origin xyz="-0.013 -0.384 -0.02" rpy="-5.72707e-17 -1.57283e-15 -1.41271e-15"/>
        <parent link="cuisse_2"/>
        <child link="vérin_m_5"/>
        <axis xyz="0 0 1"/>
        <limit effort="1" velocity="20"/>
        <joint_properties friction="0.0"/>
    </joint>

    <joint name="11" type="revolute">
        <origin xyz="0.125 -0.02 -0.04" rpy="1.5708 0.354305 1.65016e-15"/>
        <parent link="hanche_2"/>
        <child link="cuisse_2"/>
        <axis xyz="0 0 1"/>
        <limit effort="1" velocity="20"/>
        <joint_properties friction="0.0"/>
    </joint>

    <link name="vérin_m_6">
        <visual>
            <origin xyz="-0.3275 -0.0355 -6.93889e-18" rpy="1.5708 1.5708 0"/>
            <geometry>
                <mesh filename="package://vérin_m.stl"/>
            </geometry>
            <material name="vérin_m_material">
                <color rgba="0.972549 0.529412 0.00392157 1.0"/>
            </material>
        </visual>
        <collision>
            <origin xyz="-0.3275 -0.0355 -6.93889e-18" rpy="1.5708 1.5708 0"/>
            <geometry>
                <mesh filename="package://vérin_m.stl"/>
            </geometry>
            <material name="vérin_m_material">
                <color rgba="0.972549 0.529412 0.00392157 1.0"/>
            </material>
        </collision>
        <inertial>
            <origin xyz="-0.18637 4.92938e-09 -4.07398e-10" rpy="0 0 0"/>
            <mass value="1.92684"/>
            <inertia ixx="0.023605" ixy="3.04855e-11" ixz="1.08751e-09" iyy="0.0236064" iyz="1.74386e-10"
                     izz="0.00019771"/>
        </inertial>
    </link>

    <link name="vérin_f_6">
        <visual>
            <origin xyz="0 -0.0355 0.05" rpy="1.5708 4.27409e-32 -1.31337e-32"/>
            <geometry>
                <mesh filename="package://vérin_f.stl"/>
            </geometry>
            <material name="vérin_f_material">
                <color rgba="0.768627 0.886275 0.952941 1.0"/>
            </material>
        </visual>
        <collision>
            <origin xyz="0 -0.0355 0.05" rpy="1.5708 4.27409e-32 -1.31337e-32"/>
            <geometry>
                <mesh filename="package://vérin_f.stl"/>
            </geometry>
            <material name="vérin_f_material">
                <color rgba="0.768627 0.886275 0.952941 1.0"/>
            </material>
        </collision>
        <inertial>
            <origin xyz="3.32076e-10 -0.0342983 0.0718149" rpy="0 0 0"/>
            <mass value="13.8405"/>
            <inertia ixx="0.1564" ixy="1.67477e-11" ixz="-4.94005e-10" iyy="0.139129" iyz="-0.0107561" izz="0.0268384"/>
        </inertial>
    </link>

    <link name="connecteur_12">
        <visual>
            <origin xyz="0 0 1.73472e-18" rpy="1.5708 1.5708 0"/>
            <geometry>
                <mesh filename="package://connecteur.stl"/>
            </geometry>
            <material name="connecteur_material">
                <color rgba="0.498039 0.498039 0.498039 1.0"/>
            </material>
        </visual>
        <collision>
            <origin xyz="0 0 1.73472e-18" rpy="1.5708 1.5708 0"/>
            <geometry>
                <mesh filename="package://connecteur.stl"/>
            </geometry>
            <material name="connecteur_material">
                <color rgba="0.498039 0.498039 0.498039 1.0"/>
            </material>
        </collision>
        <inertial>
            <origin xyz="4.64485e-50 1.16945e-19 -4.56127e-19" rpy="0 0 0"/>
            <mass value="0.00475914"/>
            <inertia ixx="6.77384e-07" ixy="-9.15344e-40" ixz="2.73199e-38" iyy="8.56644e-08" iyz="4.94139e-38"
                     izz="6.77384e-07"/>
        </inertial>
    </link>

    <joint name="co_13" type="fixed">
        <origin xyz="0 -5.55112e-17 -0.068" rpy="2.13504e-16 1.5708 0"/>
        <parent link="vérin_f_6"/>
        <child link="connecteur_12"/>
        <axis xyz="0 0 1"/>
        <limit effort="1" velocity="20"/>
        <joint_properties friction="0.0"/>
    </joint>

    <joint name="1v3" type="prismatic">
        <origin xyz="-0.519556 5.55112e-17 -6.97185e-15" rpy="-1.53783e-14 1.5708 0"/>
        <parent link="vérin_m_6"/>
        <child link="vérin_f_6"/>
        <axis xyz="0 0 1"/>
        <limit effort="1" velocity="20" lower="-0.2045" upper="-0.0045"/>
        <joint_properties friction="0.0"/>
    </joint>

    <joint name="15" type="revolute">
        <origin xyz="0.275 -1.11022e-16 0.014" rpy="2.10014e-26 2.07112e-26 2.41444"/>
        <parent link="hanche_2"/>
        <child link="vérin_m_6"/>
        <axis xyz="0 0 1"/>
        <limit effort="1" velocity="20" lower="0" upper="0"/>
        <joint_properties friction="0.0"/>
    </joint>

    <link name="connecteur_13">
        <visual>
            <origin xyz="2.22045e-16 0 0.02" rpy="1.5708 1.5708 0"/>
            <geometry>
                <mesh filename="package://connecteur.stl"/>
            </geometry>
            <material name="connecteur_material">
                <color rgba="0.498039 0.498039 0.498039 1.0"/>
            </material>
        </visual>
        <collision>
            <origin xyz="2.22045e-16 0 0.02" rpy="1.5708 1.5708 0"/>
            <geometry>
                <mesh filename="package://connecteur.stl"/>
            </geometry>
            <material name="connecteur_material">
                <color rgba="0.498039 0.498039 0.498039 1.0"/>
            </material>
        </collision>
        <inertial>
            <origin xyz="2.22045e-16 1.16945e-19 0.02" rpy="0 0 0"/>
            <mass value="0.00475914"/>
            <inertia ixx="6.77384e-07" ixy="1.22621e-23" ixz="-3.9715e-66" iyy="8.56644e-08" iyz="-6.6896e-49"
                     izz="6.77384e-07"/>
        </inertial>
    </link>

    <joint name="co_10" type="fixed">
        <origin xyz="-0.125 0.02 -0.04" rpy="1.5708 -8.96831e-43 9.93039e-18"/>
        <parent link="hanche_2"/>
        <child link="connecteur_13"/>
        <axis xyz="0 0 1"/>
        <limit effort="1" velocity="20"/>
        <joint_properties friction="0.0"/>
    </joint>

    <link name="connecteur_14">
        <visual>
            <origin xyz="-2.22045e-16 0 1.11022e-16" rpy="1.5708 1.5708 0"/>
            <geometry>
                <mesh filename="package://connecteur.stl"/>
            </geometry>
            <material name="connecteur_material">
                <color rgba="0.498039 0.498039 0.498039 1.0"/>
            </material>
        </visual>
        <collision>
            <origin xyz="-2.22045e-16 0 1.11022e-16" rpy="1.5708 1.5708 0"/>
            <geometry>
                <mesh filename="package://connecteur.stl"/>
            </geometry>
            <material name="connecteur_material">
                <color rgba="0.498039 0.498039 0.498039 1.0"/>
            </material>
        </collision>
        <inertial>
            <origin xyz="-2.22045e-16 1.16945e-19 1.08831e-16" rpy="0 0 0"/>
            <mass value="0.00475914"/>
            <inertia ixx="6.77384e-07" ixy="1.22621e-23" ixz="-3.9715e-66" iyy="8.56644e-08" iyz="-6.6896e-49"
                     izz="6.77384e-07"/>
        </inertial>
    </link>

    <joint name="co_14" type="fixed">
        <origin xyz="-0.41 2.77556e-16 -0.095" rpy="1.5708 -8.96831e-43 9.93039e-18"/>
        <parent link="hanche_2"/>
        <child link="connecteur_14"/>
        <axis xyz="0 0 1"/>
        <limit effort="1" velocity="20"/>
        <joint_properties friction="0.0"/>
    </joint>

    <joint name="10" type="revolute">
        <origin xyz="-0.5 -1.025 0.025" rpy="-3.14159 -9.89402e-28 0.84364"/>
        <parent link="chassis"/>
        <child link="hanche_2"/>
        <axis xyz="0 0 1"/>
        <limit effort="1" velocity="20"/>
        <joint_properties friction="0.0"/>
    </joint>

    <link name="hanche_3">
        <visual>
            <origin xyz="-0.065 0 0" rpy="3.14159 3.69779e-32 -3.48221e-17"/>
            <geometry>
                <mesh filename="package://hanche.stl"/>
            </geometry>
            <material name="hanche_material">
                <color rgba="0.647059 0.647059 0.647059 1.0"/>
            </material>
        </visual>
        <collision>
            <origin xyz="-0.065 0 0" rpy="3.14159 3.69779e-32 -3.48221e-17"/>
            <geometry>
                <mesh filename="package://hanche.stl"/>
            </geometry>
            <material name="hanche_material">
                <color rgba="0.647059 0.647059 0.647059 1.0"/>
            </material>
        </collision>
        <inertial>
            <origin xyz="-0.0375418 1.02187e-17 -0.0164898" rpy="0 0 0"/>
            <mass value="6.76832"/>
            <inertia ixx="0.0155143" ixy="8.39785e-18" ixz="-0.0226558" iyy="0.237688" iyz="-1.76774e-19"
                     izz="0.241914"/>
        </inertial>
    </link>

    <link name="cuisse_3">
        <visual>
            <origin xyz="2.77556e-17 0.2425 -0.03" rpy="-1.5708 2.56485e-17 1.75337e-17"/>
            <geometry>
                <mesh filename="package://cuisse.stl"/>
            </geometry>
            <material name="cuisse_material">
                <color rgba="0.231373 0.380392 0.705882 1.0"/>
            </material>
        </visual>
        <collision>
            <origin xyz="2.77556e-17 0.2425 -0.03" rpy="-1.5708 2.56485e-17 1.75337e-17"/>
            <geometry>
                <mesh filename="package://cuisse.stl"/>
            </geometry>
            <material name="cuisse_material">
                <color rgba="0.231373 0.380392 0.705882 1.0"/>
            </material>
        </collision>
        <inertial>
            <origin xyz="0.00641397 0.245927 0.02" rpy="0 0 0"/>
            <mass value="1.51643"/>
            <inertia ixx="0.0342844" ixy="-8.38913e-05" ixz="4.96328e-11" iyy="0.00340326" iyz="-2.43061e-11"
                     izz="0.0314625"/>
        </inertial>
    </link>

    <link name="tibia_3">
        <visual>
            <origin xyz="-0.375 0 0" rpy="1.5708 -2.05763e-17 -3.15544e-30"/>
            <geometry>
                <mesh filename="package://tibia.stl"/>
            </geometry>
            <material name="tibia_material">
                <color rgba="0.917647 0.917647 0.917647 1.0"/>
            </material>
        </visual>
        <collision>
            <origin xyz="-0.375 0 0" rpy="1.5708 -2.05763e-17 -3.15544e-30"/>
            <geometry>
                <mesh filename="package://tibia.stl"/>
            </geometry>
            <material name="tibia_material">
                <color rgba="0.917647 0.917647 0.917647 1.0"/>
            </material>
        </collision>
        <inertial>
            <origin xyz="-0.374888 1.41517e-19 -0.02" rpy="0 0 0"/>
            <mass value="3.57021"/>
            <inertia ixx="0.00264577" ixy="4.26457e-18" ixz="6.19376e-31" iyy="0.195451" iyz="5.03408e-31"
                     izz="0.196288"/>
        </inertial>
    </link>

    <link name="pied_3">
        <visual>
            <origin xyz="2.22045e-16 0.3475 0.07" rpy="1.5708 9.80496e-18 -1.68819e-31"/>
            <geometry>
                <mesh filename="package://pied.stl"/>
            </geometry>
            <material name="pied_material">
                <color rgba="0.231373 0.380392 0.705882 1.0"/>
            </material>
        </visual>
        <collision>
            <origin xyz="2.22045e-16 0.3475 0.07" rpy="1.5708 9.80496e-18 -1.68819e-31"/>
            <geometry>
                <mesh filename="package://pied.stl"/>
            </geometry>
            <material name="pied_material">
                <color rgba="0.231373 0.380392 0.705882 1.0"/>
            </material>
        </collision>
        <inertial>
            <origin xyz="0.00674789 0.371096 0.02" rpy="0 0 0"/>
            <mass value="1.90862"/>
            <inertia ixx="0.14346" ixy="-0.000281054" ixz="1.66321e-08" iyy="0.00295345" iyz="1.76799e-09"
                     izz="0.141209"/>
        </inertial>
    </link>

    <link name="vérin_m_7">
        <visual>
            <origin xyz="-0.3275 -0.0355 1.11022e-16" rpy="1.5708 1.5708 0"/>
            <geometry>
                <mesh filename="package://vérin_m.stl"/>
            </geometry>
            <material name="vérin_m_material">
                <color rgba="0.972549 0.529412 0.00392157 1.0"/>
            </material>
        </visual>
        <collision>
            <origin xyz="-0.3275 -0.0355 1.11022e-16" rpy="1.5708 1.5708 0"/>
            <geometry>
                <mesh filename="package://vérin_m.stl"/>
            </geometry>
            <material name="vérin_m_material">
                <color rgba="0.972549 0.529412 0.00392157 1.0"/>
            </material>
        </collision>
        <inertial>
            <origin xyz="-0.18637 4.92938e-09 -4.07398e-10" rpy="0 0 0"/>
            <mass value="1.92684"/>
            <inertia ixx="0.023605" ixy="3.04855e-11" ixz="1.08751e-09" iyy="0.0236064" iyz="1.74386e-10"
                     izz="0.00019771"/>
        </inertial>
    </link>

    <link name="vérin_f_7">
        <visual>
            <origin xyz="0 -0.0355 0.05" rpy="1.5708 2.00322e-17 1.29646e-17"/>
            <geometry>
                <mesh filename="package://vérin_f.stl"/>
            </geometry>
            <material name="vérin_f_material">
                <color rgba="0.768627 0.886275 0.952941 1.0"/>
            </material>
        </visual>
        <collision>
            <origin xyz="0 -0.0355 0.05" rpy="1.5708 2.00322e-17 1.29646e-17"/>
            <geometry>
                <mesh filename="package://vérin_f.stl"/>
            </geometry>
            <material name="vérin_f_material">
                <color rgba="0.768627 0.886275 0.952941 1.0"/>
            </material>
        </collision>
        <inertial>
            <origin xyz="3.32076e-10 -0.0342983 0.0718149" rpy="0 0 0"/>
            <mass value="13.8405"/>
            <inertia ixx="0.1564" ixy="1.67477e-11" ixz="-4.94005e-10" iyy="0.139129" iyz="-0.0107561" izz="0.0268384"/>
        </inertial>
    </link>

    <link name="connecteur_15">
        <visual>
            <origin xyz="-1.11022e-16 0 -5.55112e-17" rpy="1.5708 1.5708 0"/>
            <geometry>
                <mesh filename="package://connecteur.stl"/>
            </geometry>
            <material name="connecteur_material">
                <color rgba="0.498039 0.498039 0.498039 1.0"/>
            </material>
        </visual>
        <collision>
            <origin xyz="-1.11022e-16 0 -5.55112e-17" rpy="1.5708 1.5708 0"/>
            <geometry>
                <mesh filename="package://connecteur.stl"/>
            </geometry>
            <material name="connecteur_material">
                <color rgba="0.498039 0.498039 0.498039 1.0"/>
            </material>
        </collision>
        <inertial>
            <origin xyz="-1.11022e-16 1.16945e-19 -5.7702e-17" rpy="0 0 0"/>
            <mass value="0.00475914"/>
            <inertia ixx="6.77384e-07" ixy="2.0412e-23" ixz="6.38661e-23" iyy="8.56644e-08" iyz="-5.88031e-23"
                     izz="6.77384e-07"/>
        </inertial>
    </link>

    <joint name="co_27" type="fixed">
        <origin xyz="-5.55112e-17 -5.55112e-17 -0.068" rpy="-2.00069e-16 -1.5708 0"/>
        <parent link="vérin_f_7"/>
        <child link="connecteur_15"/>
        <axis xyz="0 0 1"/>
        <limit effort="1" velocity="20"/>
        <joint_properties friction="0.0"/>
    </joint>

    <joint name="2v2" type="prismatic">
        <origin xyz="-0.382 0 1.66533e-15" rpy="4.83789e-15 1.5708 0"/>
        <parent link="vérin_m_7"/>
        <child link="vérin_f_7"/>
        <axis xyz="0 0 1"/>
        <limit effort="1" velocity="20" lower="-0.2045" upper="-0.0045"/>
        <joint_properties friction="0.0"/>
    </joint>

    <joint name="27" type="revolute">
        <origin xyz="2.22045e-16 0.505 0.02" rpy="-6.30891e-15 -1.38316e-14 0.354305"/>
        <parent link="pied_3"/>
        <child link="vérin_m_7"/>
        <axis xyz="0 0 1"/>
        <limit effort="1" velocity="20"/>
        <joint_properties friction="0.0"/>
    </joint>

    <joint name="23" type="revolute">
        <origin xyz="-0.75 -1.11022e-16 5.55112e-17" rpy="3.14159 -2.13958e-14 3.14159"/>
        <parent link="tibia_3"/>
        <child link="pied_3"/>
        <axis xyz="0 0 1"/>
        <limit effort="1" velocity="20"/>
        <joint_properties friction="0.0"/>
    </joint>

    <link name="support_v2_3">
        <visual>
            <origin xyz="-1.11022e-16 -0.3475 -0.03" rpy="-1.5708 -2.199e-17 7.88861e-31"/>
            <geometry>
                <mesh filename="package://support_v2.stl"/>
            </geometry>
            <material name="support_v2_material">
                <color rgba="0.231373 0.380392 0.705882 1.0"/>
            </material>
        </visual>
        <collision>
            <origin xyz="-1.11022e-16 -0.3475 -0.03" rpy="-1.5708 -2.199e-17 7.88861e-31"/>
            <geometry>
                <mesh filename="package://support_v2.stl"/>
            </geometry>
            <material name="support_v2_material">
                <color rgba="0.231373 0.380392 0.705882 1.0"/>
            </material>
        </collision>
        <inertial>
            <origin xyz="0.00543544 -0.291712 0.0201529" rpy="0 0 0"/>
            <mass value="1.58654"/>
            <inertia ixx="0.0561792" ixy="6.54178e-05" ixz="4.14017e-06" iyy="0.00372126" iyz="8.07606e-06"
                     izz="0.0530513"/>
        </inertial>
    </link>

    <link name="connecteur_16">
        <visual>
            <origin xyz="1.11022e-16 0 -0.02" rpy="-1.5708 -1.5708 0"/>
            <geometry>
                <mesh filename="package://connecteur.stl"/>
            </geometry>
            <material name="connecteur_material">
                <color rgba="0.498039 0.498039 0.498039 1.0"/>
            </material>
        </visual>
        <collision>
            <origin xyz="1.11022e-16 0 -0.02" rpy="-1.5708 -1.5708 0"/>
            <geometry>
                <mesh filename="package://connecteur.stl"/>
            </geometry>
            <material name="connecteur_material">
                <color rgba="0.498039 0.498039 0.498039 1.0"/>
            </material>
        </collision>
        <inertial>
            <origin xyz="1.11022e-16 -1.16945e-19 -0.02" rpy="0 0 0"/>
            <mass value="0.00475914"/>
            <inertia ixx="6.77384e-07" ixy="1.06923e-23" ixz="5.34361e-37" iyy="8.56644e-08" iyz="-6.01939e-37"
                     izz="6.77384e-07"/>
        </inertial>
    </link>

    <joint name="co_21" type="fixed">
        <origin xyz="-1.11022e-16 -0.59 -1.11022e-16" rpy="-3.14159 2.199e-17 -3.14159"/>
        <parent link="support_v2_3"/>
        <child link="connecteur_16"/>
        <axis xyz="0 0 1"/>
        <limit effort="1" velocity="20"/>
        <joint_properties friction="0.0"/>
    </joint>

    <link name="connecteur_17">
        <visual>
            <origin xyz="0 0 -5.55112e-17" rpy="1.5708 1.5708 0"/>
            <geometry>
                <mesh filename="package://connecteur.stl"/>
            </geometry>
            <material name="connecteur_material">
                <color rgba="0.498039 0.498039 0.498039 1.0"/>
            </material>
        </visual>
        <collision>
            <origin xyz="0 0 -5.55112e-17" rpy="1.5708 1.5708 0"/>
            <geometry>
                <mesh filename="package://connecteur.stl"/>
            </geometry>
            <material name="connecteur_material">
                <color rgba="0.498039 0.498039 0.498039 1.0"/>
            </material>
        </collision>
        <inertial>
            <origin xyz="-1.07501e-34 1.16945e-19 -5.7702e-17" rpy="0 0 0"/>
            <mass value="0.00475914"/>
            <inertia ixx="6.77384e-07" ixy="1.06923e-23" ixz="5.34361e-37" iyy="8.56644e-08" iyz="-6.01939e-37"
                     izz="6.77384e-07"/>
        </inertial>
    </link>

    <joint name="co_26" type="fixed">
        <origin xyz="0 -0.1975 0.02" rpy="1.97215e-31 2.199e-17 -3.14159"/>
        <parent link="support_v2_3"/>
        <child link="connecteur_17"/>
        <axis xyz="0 0 1"/>
        <limit effort="1" velocity="20"/>
        <joint_properties friction="0.0"/>
    </joint>

    <joint name="24" type="revolute">
        <origin xyz="-0.45 -1.11022e-16 1.11022e-16" rpy="3.14159 -2.94472e-17 -1.16985e-14"/>
        <parent link="tibia_3"/>
        <child link="support_v2_3"/>
        <axis xyz="0 0 1"/>
        <limit effort="1" velocity="20"/>
        <joint_properties friction="0.0"/>
    </joint>

    <joint name="22" type="revolute">
        <origin xyz="-2.77556e-17 0.49 0" rpy="3.14159 1.15985e-14 -0.354305"/>
        <parent link="cuisse_3"/>
        <child link="tibia_3"/>
        <axis xyz="0 0 1"/>
        <limit effort="1" velocity="20"/>
        <joint_properties friction="0.0"/>
    </joint>

    <link name="vérin_m_8">
        <visual>
            <origin xyz="-0.3275 -0.0355 -5.55112e-17" rpy="1.5708 1.5708 0"/>
            <geometry>
                <mesh filename="package://vérin_m.stl"/>
            </geometry>
            <material name="vérin_m_material">
                <color rgba="0.972549 0.529412 0.00392157 1.0"/>
            </material>
        </visual>
        <collision>
            <origin xyz="-0.3275 -0.0355 -5.55112e-17" rpy="1.5708 1.5708 0"/>
            <geometry>
                <mesh filename="package://vérin_m.stl"/>
            </geometry>
            <material name="vérin_m_material">
                <color rgba="0.972549 0.529412 0.00392157 1.0"/>
            </material>
        </collision>
        <inertial>
            <origin xyz="-0.18637 4.92938e-09 -4.07398e-10" rpy="0 0 0"/>
            <mass value="1.92684"/>
            <inertia ixx="0.023605" ixy="3.04855e-11" ixz="1.08751e-09" iyy="0.0236064" iyz="1.74386e-10"
                     izz="0.00019771"/>
        </inertial>
    </link>

    <link name="vérin_f_8">
        <visual>
            <origin xyz="-1.11022e-16 -0.0355 0.05" rpy="1.5708 -8.73747e-18 1.59733e-18"/>
            <geometry>
                <mesh filename="package://vérin_f.stl"/>
            </geometry>
            <material name="vérin_f_material">
                <color rgba="0.768627 0.886275 0.952941 1.0"/>
            </material>
        </visual>
        <collision>
            <origin xyz="-1.11022e-16 -0.0355 0.05" rpy="1.5708 -8.73747e-18 1.59733e-18"/>
            <geometry>
                <mesh filename="package://vérin_f.stl"/>
            </geometry>
            <material name="vérin_f_material">
                <color rgba="0.768627 0.886275 0.952941 1.0"/>
            </material>
        </collision>
        <inertial>
            <origin xyz="3.32076e-10 -0.0342983 0.0718149" rpy="0 0 0"/>
            <mass value="13.8405"/>
            <inertia ixx="0.1564" ixy="1.67478e-11" ixz="-4.94005e-10" iyy="0.139129" iyz="-0.0107561" izz="0.0268384"/>
        </inertial>
    </link>

    <link name="connecteur_18">
        <visual>
            <origin xyz="1.11022e-16 0 0" rpy="1.5708 1.5708 0"/>
            <geometry>
                <mesh filename="package://connecteur.stl"/>
            </geometry>
            <material name="connecteur_material">
                <color rgba="0.498039 0.498039 0.498039 1.0"/>
            </material>
        </visual>
        <collision>
            <origin xyz="1.11022e-16 0 0" rpy="1.5708 1.5708 0"/>
            <geometry>
                <mesh filename="package://connecteur.stl"/>
            </geometry>
            <material name="connecteur_material">
                <color rgba="0.498039 0.498039 0.498039 1.0"/>
            </material>
        </collision>
        <inertial>
            <origin xyz="1.11022e-16 1.16945e-19 -2.19085e-18" rpy="0 0 0"/>
            <mass value="0.00475914"/>
            <inertia ixx="6.77384e-07" ixy="3.6446e-23" ixz="2.82666e-24" iyy="8.56644e-08" iyz="-1.32616e-23"
                     izz="6.77384e-07"/>
        </inertial>
    </link>

    <joint name="co_25" type="fixed">
        <origin xyz="-1.66533e-16 0 -0.068" rpy="1.84408e-16 1.5708 0"/>
        <parent link="vérin_f_8"/>
        <child link="connecteur_18"/>
        <axis xyz="0 0 1"/>
        <limit effort="1" velocity="20"/>
        <joint_properties friction="0.0"/>
    </joint>

    <joint name="2v1" type="prismatic">
        <origin xyz="-0.382 0 -2.05391e-15" rpy="3.14159 -1.5708 0"/>
        <parent link="vérin_m_8"/>
        <child link="vérin_f_8"/>
        <axis xyz="0 0 1"/>
        <limit effort="1" velocity="20" lower="-0.2045" upper="-0.0045"/>
        <joint_properties friction="0.0"/>
    </joint>

    <joint name="26" type="revolute">
        <origin xyz="-0.013 0.384 0.02" rpy="3.28933e-15 9.22255e-17 -3.4982e-18"/>
        <parent link="cuisse_3"/>
        <child link="vérin_m_8"/>
        <axis xyz="0 0 1"/>
        <limit effort="1" velocity="20"/>
        <joint_properties friction="0.0"/>
    </joint>

    <joint name="21" type="revolute">
        <origin xyz="0.125 -0.02 -0.04" rpy="-1.5708 0.354305 1.18777e-14"/>
        <parent link="hanche_3"/>
        <child link="cuisse_3"/>
        <axis xyz="0 0 1"/>
        <limit effort="1" velocity="20"/>
        <joint_properties friction="0.0"/>
    </joint>

    <link name="vérin_m_9">
        <visual>
            <origin xyz="-0.3275 -0.0355 -7.80626e-18" rpy="1.5708 1.5708 0"/>
            <geometry>
                <mesh filename="package://vérin_m.stl"/>
            </geometry>
            <material name="vérin_m_material">
                <color rgba="0.972549 0.529412 0.00392157 1.0"/>
            </material>
        </visual>
        <collision>
            <origin xyz="-0.3275 -0.0355 -7.80626e-18" rpy="1.5708 1.5708 0"/>
            <geometry>
                <mesh filename="package://vérin_m.stl"/>
            </geometry>
            <material name="vérin_m_material">
                <color rgba="0.972549 0.529412 0.00392157 1.0"/>
            </material>
        </collision>
        <inertial>
            <origin xyz="-0.18637 4.92938e-09 -4.07398e-10" rpy="0 0 0"/>
            <mass value="1.92684"/>
            <inertia ixx="0.023605" ixy="3.04855e-11" ixz="1.08751e-09" iyy="0.0236064" iyz="1.74386e-10"
                     izz="0.00019771"/>
        </inertial>
    </link>

    <link name="vérin_f_9">
        <visual>
            <origin xyz="0 -0.0355 0.05" rpy="1.5708 -0 0"/>
            <geometry>
                <mesh filename="package://vérin_f.stl"/>
            </geometry>
            <material name="vérin_f_material">
                <color rgba="0.768627 0.886275 0.952941 1.0"/>
            </material>
        </visual>
        <collision>
            <origin xyz="0 -0.0355 0.05" rpy="1.5708 -0 0"/>
            <geometry>
                <mesh filename="package://vérin_f.stl"/>
            </geometry>
            <material name="vérin_f_material">
                <color rgba="0.768627 0.886275 0.952941 1.0"/>
            </material>
        </collision>
        <inertial>
            <origin xyz="3.32076e-10 -0.0342983 0.0718149" rpy="0 0 0"/>
            <mass value="13.8405"/>
            <inertia ixx="0.1564" ixy="1.67477e-11" ixz="-4.94005e-10" iyy="0.139129" iyz="-0.0107561" izz="0.0268384"/>
        </inertial>
    </link>

    <link name="connecteur_19">
        <visual>
            <origin xyz="0 0 1.73472e-18" rpy="1.5708 1.5708 0"/>
            <geometry>
                <mesh filename="package://connecteur.stl"/>
            </geometry>
            <material name="connecteur_material">
                <color rgba="0.498039 0.498039 0.498039 1.0"/>
            </material>
        </visual>
        <collision>
            <origin xyz="0 0 1.73472e-18" rpy="1.5708 1.5708 0"/>
            <geometry>
                <mesh filename="package://connecteur.stl"/>
            </geometry>
            <material name="connecteur_material">
                <color rgba="0.498039 0.498039 0.498039 1.0"/>
            </material>
        </collision>
        <inertial>
            <origin xyz="-8.92387e-69 1.16945e-19 -4.56127e-19" rpy="0 0 0"/>
            <mass value="0.00475914"/>
            <inertia ixx="6.77384e-07" ixy="2.08735e-39" ixz="1.04367e-39" iyy="8.56644e-08" iyz="-8.29142e-39"
                     izz="6.77384e-07"/>
        </inertial>
    </link>

    <joint name="co_23" type="fixed">
        <origin xyz="0 -5.55112e-17 -0.068" rpy="3.14159 -1.5708 0"/>
        <parent link="vérin_f_9"/>
        <child link="connecteur_19"/>
        <axis xyz="0 0 1"/>
        <limit effort="1" velocity="20"/>
        <joint_properties friction="0.0"/>
    </joint>

    <joint name="2v3" type="prismatic">
        <origin xyz="-0.513704 -2.27596e-15 -1.07032e-15" rpy="-2.12817e-16 1.5708 0"/>
        <parent link="vérin_m_9"/>
        <child link="vérin_f_9"/>
        <axis xyz="0 0 1"/>
        <limit effort="1" velocity="20" lower="-0.2045" upper="-0.0045"/>
        <joint_properties friction="0.0"/>
    </joint>

    <joint name="25" type="revolute">
        <origin xyz="0.275 -3.21965e-15 0.03" rpy="-1.25317e-15 1.02095e-15 2.44705"/>
        <parent link="hanche_3"/>
        <child link="vérin_m_9"/>
        <axis xyz="0 0 1"/>
        <limit effort="1" velocity="20" lower="0" upper="0"/>
        <joint_properties friction="0.0"/>
    </joint>

    <link name="connecteur_20">
        <visual>
            <origin xyz="-5.55112e-17 0 -0.02" rpy="1.5708 1.5708 0"/>
            <geometry>
                <mesh filename="package://connecteur.stl"/>
            </geometry>
            <material name="connecteur_material">
                <color rgba="0.498039 0.498039 0.498039 1.0"/>
            </material>
        </visual>
        <collision>
            <origin xyz="-5.55112e-17 0 -0.02" rpy="1.5708 1.5708 0"/>
            <geometry>
                <mesh filename="package://connecteur.stl"/>
            </geometry>
            <material name="connecteur_material">
                <color rgba="0.498039 0.498039 0.498039 1.0"/>
            </material>
        </collision>
        <inertial>
            <origin xyz="-5.55112e-17 1.16945e-19 -0.02" rpy="0 0 0"/>
            <mass value="0.00475914"/>
            <inertia ixx="6.77384e-07" ixy="-4.12407e-23" ixz="1.3359e-37" iyy="8.56644e-08" iyz="-1.34646e-37"
                     izz="6.77384e-07"/>
        </inertial>
    </link>

    <joint name="co_20" type="fixed">
        <origin xyz="-0.125 -0.02 -0.04" rpy="-1.5708 -2.46519e-32 -3.14159"/>
        <parent link="hanche_3"/>
        <child link="connecteur_20"/>
        <axis xyz="0 0 1"/>
        <limit effort="1" velocity="20"/>
        <joint_properties friction="0.0"/>
    </joint>

    <link name="connecteur_21">
        <visual>
            <origin xyz="1.11022e-16 1.38778e-17 5.55112e-17" rpy="1.5708 1.5708 0"/>
            <geometry>
                <mesh filename="package://connecteur.stl"/>
            </geometry>
            <material name="connecteur_material">
                <color rgba="0.498039 0.498039 0.498039 1.0"/>
            </material>
        </visual>
        <collision>
            <origin xyz="1.11022e-16 1.38778e-17 5.55112e-17" rpy="1.5708 1.5708 0"/>
            <geometry>
                <mesh filename="package://connecteur.stl"/>
            </geometry>
            <material name="connecteur_material">
                <color rgba="0.498039 0.498039 0.498039 1.0"/>
            </material>
        </collision>
        <inertial>
            <origin xyz="1.11022e-16 1.39947e-17 5.33203e-17" rpy="0 0 0"/>
            <mass value="0.00475914"/>
            <inertia ixx="6.77384e-07" ixy="1.06923e-23" ixz="-1.3359e-37" iyy="8.56644e-08" iyz="-5.73899e-38"
                     izz="6.77384e-07"/>
        </inertial>
    </link>

    <joint name="co_24" type="fixed">
        <origin xyz="-0.41 0 -0.095" rpy="1.5708 -1.2326e-32 3.14159"/>
        <parent link="hanche_3"/>
        <child link="connecteur_21"/>
        <axis xyz="0 0 1"/>
        <limit effort="1" velocity="20"/>
        <joint_properties friction="0.0"/>
    </joint>

    <joint name="20" type="revolute">
        <origin xyz="0.5 -0.025 0.025" rpy="3.14159 -6.04163e-17 -2.26534"/>
        <parent link="chassis"/>
        <child link="hanche_3"/>
        <axis xyz="0 0 1"/>
        <limit effort="1" velocity="20"/>
        <joint_properties friction="0.0"/>
    </joint>

    <link name="hanche_4">
        <visual>
            <origin xyz="-0.065 -5.55112e-17 0" rpy="-3.14159 -0 -2.14057e-17"/>
            <geometry>
                <mesh filename="package://hanche.stl"/>
            </geometry>
            <material name="hanche_material">
                <color rgba="0.647059 0.647059 0.647059 1.0"/>
            </material>
        </visual>
        <collision>
            <origin xyz="-0.065 -5.55112e-17 0" rpy="-3.14159 -0 -2.14057e-17"/>
            <geometry>
                <mesh filename="package://hanche.stl"/>
            </geometry>
            <material name="hanche_material">
                <color rgba="0.647059 0.647059 0.647059 1.0"/>
            </material>
        </collision>
        <inertial>
            <origin xyz="-0.0375418 -4.49241e-17 -0.0164898" rpy="0 0 0"/>
            <mass value="6.76832"/>
            <inertia ixx="0.0155143" ixy="4.55874e-18" ixz="-0.0226558" iyy="0.237688" iyz="7.72687e-19"
                     izz="0.241914"/>
        </inertial>
    </link>

    <link name="cuisse_4">
        <visual>
            <origin xyz="-8.32667e-17 0.2425 -0.03" rpy="-1.5708 8.49088e-17 4.41851e-17"/>
            <geometry>
                <mesh filename="package://cuisse.stl"/>
            </geometry>
            <material name="cuisse_material">
                <color rgba="0.231373 0.380392 0.705882 1.0"/>
            </material>
        </visual>
        <collision>
            <origin xyz="-8.32667e-17 0.2425 -0.03" rpy="-1.5708 8.49088e-17 4.41851e-17"/>
            <geometry>
                <mesh filename="package://cuisse.stl"/>
            </geometry>
            <material name="cuisse_material">
                <color rgba="0.231373 0.380392 0.705882 1.0"/>
            </material>
        </collision>
        <inertial>
            <origin xyz="0.00641397 0.245927 0.02" rpy="0 0 0"/>
            <mass value="1.51643"/>
            <inertia ixx="0.0342844" ixy="-8.38913e-05" ixz="4.96328e-11" iyy="0.00340326" iyz="-2.43061e-11"
                     izz="0.0314625"/>
        </inertial>
    </link>

    <link name="tibia_4">
        <visual>
            <origin xyz="-0.375 0 -0.04" rpy="-1.5708 4.28847e-17 8.7037e-31"/>
            <geometry>
                <mesh filename="package://tibia.stl"/>
            </geometry>
            <material name="tibia_material">
                <color rgba="0.917647 0.917647 0.917647 1.0"/>
            </material>
        </visual>
        <collision>
            <origin xyz="-0.375 0 -0.04" rpy="-1.5708 4.28847e-17 8.7037e-31"/>
            <geometry>
                <mesh filename="package://tibia.stl"/>
            </geometry>
            <material name="tibia_material">
                <color rgba="0.917647 0.917647 0.917647 1.0"/>
            </material>
        </collision>
        <inertial>
            <origin xyz="-0.374888 -1.41517e-19 -0.02" rpy="0 0 0"/>
            <mass value="3.57021"/>
            <inertia ixx="0.00264577" ixy="8.36965e-18" ixz="1.68468e-31" iyy="0.195451" iyz="-1.89327e-31"
                     izz="0.196288"/>
        </inertial>
    </link>

    <link name="pied_4">
        <visual>
            <origin xyz="0 0.3475 0.07" rpy="1.5708 -3.19122e-18 1.57772e-30"/>
            <geometry>
                <mesh filename="package://pied.stl"/>
            </geometry>
            <material name="pied_material">
                <color rgba="0.231373 0.380392 0.705882 1.0"/>
            </material>
        </visual>
        <collision>
            <origin xyz="0 0.3475 0.07" rpy="1.5708 -3.19122e-18 1.57772e-30"/>
            <geometry>
                <mesh filename="package://pied.stl"/>
            </geometry>
            <material name="pied_material">
                <color rgba="0.231373 0.380392 0.705882 1.0"/>
            </material>
        </collision>
        <inertial>
            <origin xyz="0.00674789 0.371096 0.02" rpy="0 0 0"/>
            <mass value="1.90862"/>
            <inertia ixx="0.14346" ixy="-0.000281054" ixz="1.66321e-08" iyy="0.00295345" iyz="1.76799e-09"
                     izz="0.141209"/>
        </inertial>
    </link>

    <link name="vérin_m_10">
        <visual>
            <origin xyz="-0.3275 -0.0355 0" rpy="1.5708 1.5708 0"/>
            <geometry>
                <mesh filename="package://vérin_m.stl"/>
            </geometry>
            <material name="vérin_m_material">
                <color rgba="0.972549 0.529412 0.00392157 1.0"/>
            </material>
        </visual>
        <collision>
            <origin xyz="-0.3275 -0.0355 0" rpy="1.5708 1.5708 0"/>
            <geometry>
                <mesh filename="package://vérin_m.stl"/>
            </geometry>
            <material name="vérin_m_material">
                <color rgba="0.972549 0.529412 0.00392157 1.0"/>
            </material>
        </collision>
        <inertial>
            <origin xyz="-0.18637 4.92938e-09 -4.07398e-10" rpy="0 0 0"/>
            <mass value="1.92684"/>
            <inertia ixx="0.023605" ixy="3.04855e-11" ixz="1.08751e-09" iyy="0.0236064" iyz="1.74386e-10"
                     izz="0.00019771"/>
        </inertial>
    </link>

    <link name="vérin_f_10">
        <visual>
            <origin xyz="0 -0.0355 0.05" rpy="1.5708 4.70619e-17 -9.5419e-18"/>
            <geometry>
                <mesh filename="package://vérin_f.stl"/>
            </geometry>
            <material name="vérin_f_material">
                <color rgba="0.768627 0.886275 0.952941 1.0"/>
            </material>
        </visual>
        <collision>
            <origin xyz="0 -0.0355 0.05" rpy="1.5708 4.70619e-17 -9.5419e-18"/>
            <geometry>
                <mesh filename="package://vérin_f.stl"/>
            </geometry>
            <material name="vérin_f_material">
                <color rgba="0.768627 0.886275 0.952941 1.0"/>
            </material>
        </collision>
        <inertial>
            <origin xyz="3.32076e-10 -0.0342983 0.0718149" rpy="0 0 0"/>
            <mass value="13.8405"/>
            <inertia ixx="0.1564" ixy="1.67477e-11" ixz="-4.94005e-10" iyy="0.139129" iyz="-0.0107561" izz="0.0268384"/>
        </inertial>
    </link>

    <link name="connecteur_22">
        <visual>
            <origin xyz="-1.11022e-16 5.55112e-17 0" rpy="1.5708 1.5708 0"/>
            <geometry>
                <mesh filename="package://connecteur.stl"/>
            </geometry>
            <material name="connecteur_material">
                <color rgba="0.498039 0.498039 0.498039 1.0"/>
            </material>
        </visual>
        <collision>
            <origin xyz="-1.11022e-16 5.55112e-17 0" rpy="1.5708 1.5708 0"/>
            <geometry>
                <mesh filename="package://connecteur.stl"/>
            </geometry>
            <material name="connecteur_material">
                <color rgba="0.498039 0.498039 0.498039 1.0"/>
            </material>
        </collision>
        <inertial>
            <origin xyz="-1.11022e-16 5.56281e-17 -2.19085e-18" rpy="0 0 0"/>
            <mass value="0.00475914"/>
            <inertia ixx="6.77384e-07" ixy="-1.03061e-23" ixz="-1.61389e-24" iyy="8.56644e-08" iyz="-1.50062e-23"
                     izz="6.77384e-07"/>
        </inertial>
    </link>

    <joint name="co_37" type="fixed">
        <origin xyz="1.66533e-16 5.55112e-17 -0.068" rpy="-2.30428e-16 -1.5708 0"/>
        <parent link="vérin_f_10"/>
        <child link="connecteur_22"/>
        <axis xyz="0 0 1"/>
        <limit effort="1" velocity="20"/>
        <joint_properties friction="0.0"/>
    </joint>

    <joint name="3v2" type="prismatic">
        <origin xyz="-0.382 5.55112e-17 5.55112e-17" rpy="-6.86649e-17 1.5708 0"/>
        <parent link="vérin_m_10"/>
        <child link="vérin_f_10"/>
        <axis xyz="0 0 1"/>
        <limit effort="1" velocity="20" lower="-0.2045" upper="-0.0045"/>
        <joint_properties friction="0.0"/>
    </joint>

    <joint name="37" type="revolute">
        <origin xyz="0 0.505 0.02" rpy="6.43438e-17 3.37379e-16 0.354305"/>
        <parent link="pied_4"/>
        <child link="vérin_m_10"/>
        <axis xyz="0 0 1"/>
        <limit effort="1" velocity="20"/>
        <joint_properties friction="0.0"/>
    </joint>

    <joint name="33" type="revolute">
        <origin xyz="-0.75 -1.11022e-16 -0.04" rpy="6.91417e-17 -2.20668e-17 3.14159"/>
        <parent link="tibia_4"/>
        <child link="pied_4"/>
        <axis xyz="0 0 1"/>
        <limit effort="1" velocity="20"/>
        <joint_properties friction="0.0"/>
    </joint>

    <link name="support_v2_4">
        <visual>
            <origin xyz="1.11022e-16 -0.3475 -0.03" rpy="-1.5708 -1.41554e-17 -3.15544e-30"/>
            <geometry>
                <mesh filename="package://support_v2.stl"/>
            </geometry>
            <material name="support_v2_material">
                <color rgba="0.231373 0.380392 0.705882 1.0"/>
            </material>
        </visual>
        <collision>
            <origin xyz="1.11022e-16 -0.3475 -0.03" rpy="-1.5708 -1.41554e-17 -3.15544e-30"/>
            <geometry>
                <mesh filename="package://support_v2.stl"/>
            </geometry>
            <material name="support_v2_material">
                <color rgba="0.231373 0.380392 0.705882 1.0"/>
            </material>
        </collision>
        <inertial>
            <origin xyz="0.00543544 -0.291712 0.0201529" rpy="0 0 0"/>
            <mass value="1.58654"/>
            <inertia ixx="0.0561792" ixy="6.54178e-05" ixz="4.14017e-06" iyy="0.00372126" iyz="8.07606e-06"
                     izz="0.0530513"/>
        </inertial>
    </link>

    <link name="connecteur_23">
        <visual>
            <origin xyz="0 -1.38778e-17 0.02" rpy="1.5708 1.5708 0"/>
            <geometry>
                <mesh filename="package://connecteur.stl"/>
            </geometry>
            <material name="connecteur_material">
                <color rgba="0.498039 0.498039 0.498039 1.0"/>
            </material>
        </visual>
        <collision>
            <origin xyz="0 -1.38778e-17 0.02" rpy="1.5708 1.5708 0"/>
            <geometry>
                <mesh filename="package://connecteur.stl"/>
            </geometry>
            <material name="connecteur_material">
                <color rgba="0.498039 0.498039 0.498039 1.0"/>
            </material>
        </collision>
        <inertial>
            <origin xyz="-2.51425e-34 -1.37608e-17 0.02" rpy="0 0 0"/>
            <mass value="0.00475914"/>
            <inertia ixx="6.77384e-07" ixy="-9.53624e-23" ixz="4.00771e-37" iyy="8.56644e-08" iyz="2.70309e-37"
                     izz="6.77384e-07"/>
        </inertial>
    </link>

    <joint name="co_31" type="fixed">
        <origin xyz="1.11022e-16 -0.59 0.04" rpy="3.14159 7.19322e-16 -3.14159"/>
        <parent link="support_v2_4"/>
        <child link="connecteur_23"/>
        <axis xyz="0 0 1"/>
        <limit effort="1" velocity="20"/>
        <joint_properties friction="0.0"/>
    </joint>

    <link name="connecteur_24">
        <visual>
            <origin xyz="0 5.55112e-17 5.55112e-17" rpy="1.5708 1.5708 0"/>
            <geometry>
                <mesh filename="package://connecteur.stl"/>
            </geometry>
            <material name="connecteur_material">
                <color rgba="0.498039 0.498039 0.498039 1.0"/>
            </material>
        </visual>
        <collision>
            <origin xyz="0 5.55112e-17 5.55112e-17" rpy="1.5708 1.5708 0"/>
            <geometry>
                <mesh filename="package://connecteur.stl"/>
            </geometry>
            <material name="connecteur_material">
                <color rgba="0.498039 0.498039 0.498039 1.0"/>
            </material>
        </collision>
        <inertial>
            <origin xyz="2.86343e-35 5.56281e-17 5.33203e-17" rpy="0 0 0"/>
            <mass value="0.00475914"/>
            <inertia ixx="6.77384e-07" ixy="1.07083e-23" ixz="3.67374e-37" iyy="8.56644e-08" iyz="2.40776e-36"
                     izz="6.77384e-07"/>
        </inertial>
    </link>

    <joint name="co_36" type="fixed">
        <origin xyz="1.11022e-16 -0.1975 0.02" rpy="7.88861e-31 1.41554e-17 3.14159"/>
        <parent link="support_v2_4"/>
        <child link="connecteur_24"/>
        <axis xyz="0 0 1"/>
        <limit effort="1" velocity="20"/>
        <joint_properties friction="0.0"/>
    </joint>

    <joint name="34" type="revolute">
        <origin xyz="-0.45 0 -0.04" rpy="4.9948e-16 4.48809e-16 -8.19875e-15"/>
        <parent link="tibia_4"/>
        <child link="support_v2_4"/>
        <axis xyz="0 0 1"/>
        <limit effort="1" velocity="20"/>
        <joint_properties friction="0.0"/>
    </joint>

    <joint name="32" type="revolute">
        <origin xyz="1.11022e-16 0.49 0.04" rpy="-7.10909e-17 3.67917e-16 -0.354305"/>
        <parent link="cuisse_4"/>
        <child link="tibia_4"/>
        <axis xyz="0 0 1"/>
        <limit effort="1" velocity="20"/>
        <joint_properties friction="0.0"/>
    </joint>

    <link name="vérin_m_11">
        <visual>
            <origin xyz="-0.3275 -0.0355 0" rpy="1.5708 1.5708 0"/>
            <geometry>
                <mesh filename="package://vérin_m.stl"/>
            </geometry>
            <material name="vérin_m_material">
                <color rgba="0.972549 0.529412 0.00392157 1.0"/>
            </material>
        </visual>
        <collision>
            <origin xyz="-0.3275 -0.0355 0" rpy="1.5708 1.5708 0"/>
            <geometry>
                <mesh filename="package://vérin_m.stl"/>
            </geometry>
            <material name="vérin_m_material">
                <color rgba="0.972549 0.529412 0.00392157 1.0"/>
            </material>
        </collision>
        <inertial>
            <origin xyz="-0.18637 4.92938e-09 -4.07398e-10" rpy="0 0 0"/>
            <mass value="1.92684"/>
            <inertia ixx="0.023605" ixy="3.04855e-11" ixz="1.08751e-09" iyy="0.0236064" iyz="1.74386e-10"
                     izz="0.00019771"/>
        </inertial>
    </link>

    <link name="vérin_f_11">
        <visual>
            <origin xyz="5.55112e-17 -0.0355 0.05" rpy="1.5708 -3.41705e-17 2.90006e-17"/>
            <geometry>
                <mesh filename="package://vérin_f.stl"/>
            </geometry>
            <material name="vérin_f_material">
                <color rgba="0.768627 0.886275 0.952941 1.0"/>
            </material>
        </visual>
        <collision>
            <origin xyz="5.55112e-17 -0.0355 0.05" rpy="1.5708 -3.41705e-17 2.90006e-17"/>
            <geometry>
                <mesh filename="package://vérin_f.stl"/>
            </geometry>
            <material name="vérin_f_material">
                <color rgba="0.768627 0.886275 0.952941 1.0"/>
            </material>
        </collision>
        <inertial>
            <origin xyz="3.32076e-10 -0.0342983 0.0718149" rpy="0 0 0"/>
            <mass value="13.8405"/>
            <inertia ixx="0.1564" ixy="1.67477e-11" ixz="-4.94005e-10" iyy="0.139129" iyz="-0.0107561" izz="0.0268384"/>
        </inertial>
    </link>

    <link name="connecteur_25">
        <visual>
            <origin xyz="-1.11022e-16 0 1.11022e-16" rpy="1.5708 1.5708 0"/>
            <geometry>
                <mesh filename="package://connecteur.stl"/>
            </geometry>
            <material name="connecteur_material">
                <color rgba="0.498039 0.498039 0.498039 1.0"/>
            </material>
        </visual>
        <collision>
            <origin xyz="-1.11022e-16 0 1.11022e-16" rpy="1.5708 1.5708 0"/>
            <geometry>
                <mesh filename="package://connecteur.stl"/>
            </geometry>
            <material name="connecteur_material">
                <color rgba="0.498039 0.498039 0.498039 1.0"/>
            </material>
        </collision>
        <inertial>
            <origin xyz="-1.11022e-16 1.16945e-19 1.08831e-16" rpy="0 0 0"/>
            <mass value="0.00475914"/>
            <inertia ixx="6.77384e-07" ixy="1.9008e-23" ixz="-7.25431e-25" iyy="8.56644e-08" iyz="-1.48374e-23"
                     izz="6.77384e-07"/>
        </inertial>
    </link>

    <joint name="co_35" type="fixed">
        <origin xyz="5.55112e-17 0 -0.068" rpy="2.077e-16 1.5708 0"/>
        <parent link="vérin_f_11"/>
        <child link="connecteur_25"/>
        <axis xyz="0 0 1"/>
        <limit effort="1" velocity="20"/>
        <joint_properties friction="0.0"/>
    </joint>

    <joint name="3v1" type="prismatic">
        <origin xyz="-0.382 0 0" rpy="3.11643e-16 1.5708 0"/>
        <parent link="vérin_m_11"/>
        <child link="vérin_f_11"/>
        <axis xyz="0 0 1"/>
        <limit effort="1" velocity="20" lower="-0.2045" upper="-0.0045"/>
        <joint_properties friction="0.0"/>
    </joint>

    <joint name="36" type="revolute">
        <origin xyz="-0.013 0.384 0.02" rpy="3.14159 2.50574e-16 -3.40945e-16"/>
        <parent link="cuisse_4"/>
        <child link="vérin_m_11"/>
        <axis xyz="0 0 1"/>
        <limit effort="1" velocity="20"/>
        <joint_properties friction="0.0"/>
    </joint>

    <joint name="31" type="revolute">
        <origin xyz="0.125 -0.02 -0.04" rpy="-1.5708 0.354305 1.35977e-16"/>
        <parent link="hanche_4"/>
        <child link="cuisse_4"/>
        <axis xyz="0 0 1"/>
        <limit effort="1" velocity="20"/>
        <joint_properties friction="0.0"/>
    </joint>

    <link name="vérin_m_12">
        <visual>
            <origin xyz="-0.3275 -0.0355 -6.93889e-18" rpy="1.5708 1.5708 0"/>
            <geometry>
                <mesh filename="package://vérin_m.stl"/>
            </geometry>
            <material name="vérin_m_material">
                <color rgba="0.972549 0.529412 0.00392157 1.0"/>
            </material>
        </visual>
        <collision>
            <origin xyz="-0.3275 -0.0355 -6.93889e-18" rpy="1.5708 1.5708 0"/>
            <geometry>
                <mesh filename="package://vérin_m.stl"/>
            </geometry>
            <material name="vérin_m_material">
                <color rgba="0.972549 0.529412 0.00392157 1.0"/>
            </material>
        </collision>
        <inertial>
            <origin xyz="-0.18637 4.92938e-09 -4.07398e-10" rpy="0 0 0"/>
            <mass value="1.92684"/>
            <inertia ixx="0.023605" ixy="3.04855e-11" ixz="1.08751e-09" iyy="0.0236064" iyz="1.74386e-10"
                     izz="0.00019771"/>
        </inertial>
    </link>

    <link name="vérin_f_12">
        <visual>
            <origin xyz="1.73472e-18 -0.0355 0.05" rpy="1.5708 7.93279e-34 -2.67027e-36"/>
            <geometry>
                <mesh filename="package://vérin_f.stl"/>
            </geometry>
            <material name="vérin_f_material">
                <color rgba="0.768627 0.886275 0.952941 1.0"/>
            </material>
        </visual>
        <collision>
            <origin xyz="1.73472e-18 -0.0355 0.05" rpy="1.5708 7.93279e-34 -2.67027e-36"/>
            <geometry>
                <mesh filename="package://vérin_f.stl"/>
            </geometry>
            <material name="vérin_f_material">
                <color rgba="0.768627 0.886275 0.952941 1.0"/>
            </material>
        </collision>
        <inertial>
            <origin xyz="3.32076e-10 -0.0342983 0.0718149" rpy="0 0 0"/>
            <mass value="13.8405"/>
            <inertia ixx="0.1564" ixy="1.67477e-11" ixz="-4.94005e-10" iyy="0.139129" iyz="-0.0107561" izz="0.0268384"/>
        </inertial>
    </link>

    <link name="connecteur_26">
        <visual>
            <origin xyz="0 0 1.73472e-18" rpy="1.5708 1.5708 0"/>
            <geometry>
                <mesh filename="package://connecteur.stl"/>
            </geometry>
            <material name="connecteur_material">
                <color rgba="0.498039 0.498039 0.498039 1.0"/>
            </material>
        </visual>
        <collision>
            <origin xyz="0 0 1.73472e-18" rpy="1.5708 1.5708 0"/>
            <geometry>
                <mesh filename="package://connecteur.stl"/>
            </geometry>
            <material name="connecteur_material">
                <color rgba="0.498039 0.498039 0.498039 1.0"/>
            </material>
        </collision>
        <inertial>
            <origin xyz="-9.92082e-66 1.16945e-19 -4.56127e-19" rpy="0 0 0"/>
            <mass value="0.00475914"/>
            <inertia ixx="6.77384e-07" ixy="-5.37354e-40" ixz="1.77868e-38" iyy="8.56644e-08" iyz="3.68176e-38"
                     izz="6.77384e-07"/>
        </inertial>
    </link>

    <joint name="co_33" type="fixed">
        <origin xyz="1.73472e-18 -2.77556e-17 -0.068" rpy="2.22646e-16 1.5708 0"/>
        <parent link="vérin_f_12"/>
        <child link="connecteur_26"/>
        <axis xyz="0 0 1"/>
        <limit effort="1" velocity="20"/>
        <joint_properties friction="0.0"/>
    </joint>

    <joint name="3v3" type="prismatic">
        <origin xyz="-0.495117 -1.15463e-14 -6.05592e-15" rpy="-1.15904e-15 1.5708 0"/>
        <parent link="vérin_m_12"/>
        <child link="vérin_f_12"/>
        <axis xyz="0 0 1"/>
        <limit effort="1" velocity="20" lower="-0.2045" upper="-0.0045"/>
        <joint_properties friction="0.0"/>
    </joint>

    <joint name="35" type="revolute">
        <origin xyz="0.275 0 0.014" rpy="-1.11473e-16 -1.06957e-16 2.56064"/>
        <parent link="hanche_4"/>
        <child link="vérin_m_12"/>
        <axis xyz="0 0 1"/>
        <limit effort="1" velocity="20" lower="0" upper="0"/>
        <joint_properties friction="0.0"/>
    </joint>

    <link name="connecteur_27">
        <visual>
            <origin xyz="-1.11022e-16 0 -0.02" rpy="-1.5708 -1.5708 0"/>
            <geometry>
                <mesh filename="package://connecteur.stl"/>
            </geometry>
            <material name="connecteur_material">
                <color rgba="0.498039 0.498039 0.498039 1.0"/>
            </material>
        </visual>
        <collision>
            <origin xyz="-1.11022e-16 0 -0.02" rpy="-1.5708 -1.5708 0"/>
            <geometry>
                <mesh filename="package://connecteur.stl"/>
            </geometry>
            <material name="connecteur_material">
                <color rgba="0.498039 0.498039 0.498039 1.0"/>
            </material>
        </collision>
        <inertial>
            <origin xyz="-1.11022e-16 -1.16945e-19 -0.02" rpy="0 0 0"/>
            <mass value="0.00475914"/>
            <inertia ixx="6.77384e-07" ixy="-8.84755e-24" ixz="3.93925e-50" iyy="8.56644e-08" iyz="0"
                     izz="6.77384e-07"/>
        </inertial>
    </link>

    <joint name="co_30" type="fixed">
        <origin xyz="-0.125 -0.02 -0.04" rpy="-1.5708 -2.08062e-29 -3.14159"/>
        <parent link="hanche_4"/>
        <child link="connecteur_27"/>
        <axis xyz="0 0 1"/>
        <limit effort="1" velocity="20"/>
        <joint_properties friction="0.0"/>
    </joint>

    <link name="connecteur_28">
        <visual>
            <origin xyz="-1.11022e-16 0 5.55112e-17" rpy="1.5708 1.5708 0"/>
            <geometry>
                <mesh filename="package://connecteur.stl"/>
            </geometry>
            <material name="connecteur_material">
                <color rgba="0.498039 0.498039 0.498039 1.0"/>
            </material>
        </visual>
        <collision>
            <origin xyz="-1.11022e-16 0 5.55112e-17" rpy="1.5708 1.5708 0"/>
            <geometry>
                <mesh filename="package://connecteur.stl"/>
            </geometry>
            <material name="connecteur_material">
                <color rgba="0.498039 0.498039 0.498039 1.0"/>
            </material>
        </collision>
        <inertial>
            <origin xyz="-1.11022e-16 1.16945e-19 5.33203e-17" rpy="0 0 0"/>
            <mass value="0.00475914"/>
            <inertia ixx="6.77384e-07" ixy="-8.84755e-24" ixz="3.93925e-50" iyy="8.56644e-08" iyz="0"
                     izz="6.77384e-07"/>
        </inertial>
    </link>

    <joint name="co_34" type="fixed">
        <origin xyz="-0.41 -5.55112e-17 -0.095" rpy="1.5708 -2.08062e-29 -3.14159"/>
        <parent link="hanche_4"/>
        <child link="connecteur_28"/>
        <axis xyz="0 0 1"/>
        <limit effort="1" velocity="20"/>
        <joint_properties friction="0.0"/>
    </joint>

    <joint name="30" type="revolute">
        <origin xyz="-0.5 -0.025 0.025" rpy="3.14159 -9.82822e-28 -0.580955"/>
        <parent link="chassis"/>
        <child link="hanche_4"/>
        <axis xyz="0 0 1"/>
        <limit effort="1" velocity="20"/>
        <joint_properties friction="0.0"/>
    </joint>

    <link name="connecteur_29">
        <visual>
            <origin xyz="0 0 1.73472e-18" rpy="1.5708 1.5708 0"/>
            <geometry>
                <mesh filename="package://connecteur.stl"/>
            </geometry>
            <material name="connecteur_material">
                <color rgba="0.498039 0.498039 0.498039 1.0"/>
            </material>
        </visual>
        <collision>
            <origin xyz="0 0 1.73472e-18" rpy="1.5708 1.5708 0"/>
            <geometry>
                <mesh filename="package://connecteur.stl"/>
            </geometry>
            <material name="connecteur_material">
                <color rgba="0.498039 0.498039 0.498039 1.0"/>
            </material>
        </collision>
        <inertial>
            <origin xyz="0 1.16945e-19 -4.56127e-19" rpy="0 0 0"/>
            <mass value="0.00475914"/>
            <inertia ixx="6.77384e-07" ixy="0" ixz="0" iyy="8.56644e-08" iyz="0" izz="6.77384e-07"/>
        </inertial>
    </link>

    <joint name="co_02" type="fixed">
        <origin xyz="-0.19 -0.965 1.07553e-16" rpy="0 -0 -1.5708"/>
        <parent link="chassis"/>
        <child link="connecteur_29"/>
        <axis xyz="0 0 1"/>
        <limit effort="1" velocity="20"/>
        <joint_properties friction="0.0"/>
    </joint>

    <link name="connecteur_30">
        <visual>
            <origin xyz="0 0 1.73472e-18" rpy="1.5708 1.5708 0"/>
            <geometry>
                <mesh filename="package://connecteur.stl"/>
            </geometry>
            <material name="connecteur_material">
                <color rgba="0.498039 0.498039 0.498039 1.0"/>
            </material>
        </visual>
        <collision>
            <origin xyz="0 0 1.73472e-18" rpy="1.5708 1.5708 0"/>
            <geometry>
                <mesh filename="package://connecteur.stl"/>
            </geometry>
            <material name="connecteur_material">
                <color rgba="0.498039 0.498039 0.498039 1.0"/>
            </material>
        </collision>
        <inertial>
            <origin xyz="0 1.16945e-19 -4.56127e-19" rpy="0 0 0"/>
            <mass value="0.00475914"/>
            <inertia ixx="6.77384e-07" ixy="0" ixz="0" iyy="8.56644e-08" iyz="0" izz="6.77384e-07"/>
        </inertial>
    </link>

    <joint name="co_12" type="fixed">
        <origin xyz="-0.44 -0.335 1.09288e-16" rpy="0 -0 -1.5708"/>
        <parent link="chassis"/>
        <child link="connecteur_30"/>
        <axis xyz="0 0 1"/>
        <limit effort="1" velocity="20"/>
        <joint_properties friction="0.0"/>
    </joint>

    <link name="connecteur_31">
        <visual>
            <origin xyz="0 0 1.73472e-18" rpy="1.5708 1.5708 0"/>
            <geometry>
                <mesh filename="package://connecteur.stl"/>
            </geometry>
            <material name="connecteur_material">
                <color rgba="0.498039 0.498039 0.498039 1.0"/>
            </material>
        </visual>
        <collision>
            <origin xyz="0 0 1.73472e-18" rpy="1.5708 1.5708 0"/>
            <geometry>
                <mesh filename="package://connecteur.stl"/>
            </geometry>
            <material name="connecteur_material">
                <color rgba="0.498039 0.498039 0.498039 1.0"/>
            </material>
        </collision>
        <inertial>
            <origin xyz="0 1.16945e-19 -4.56127e-19" rpy="0 0 0"/>
            <mass value="0.00475914"/>
            <inertia ixx="6.77384e-07" ixy="0" ixz="0" iyy="8.56644e-08" iyz="0" izz="6.77384e-07"/>
        </inertial>
    </link>

    <joint name="co_22" type="fixed">
        <origin xyz="0.44 -0.715 1.09288e-16" rpy="0 -0 -1.5708"/>
        <parent link="chassis"/>
        <child link="connecteur_31"/>
        <axis xyz="0 0 1"/>
        <limit effort="1" velocity="20"/>
        <joint_properties friction="0.0"/>
    </joint>

    <link name="connecteur_32">
        <visual>
            <origin xyz="0 0 1.73472e-18" rpy="1.5708 1.5708 0"/>
            <geometry>
                <mesh filename="package://connecteur.stl"/>
            </geometry>
            <material name="connecteur_material">
                <color rgba="0.498039 0.498039 0.498039 1.0"/>
            </material>
        </visual>
        <collision>
            <origin xyz="0 0 1.73472e-18" rpy="1.5708 1.5708 0"/>
            <geometry>
                <mesh filename="package://connecteur.stl"/>
            </geometry>
            <material name="connecteur_material">
                <color rgba="0.498039 0.498039 0.498039 1.0"/>
            </material>
        </collision>
        <inertial>
            <origin xyz="0 1.16945e-19 -4.56127e-19" rpy="0 0 0"/>
            <mass value="0.00475914"/>
            <inertia ixx="6.77384e-07" ixy="0" ixz="0" iyy="8.56644e-08" iyz="0" izz="6.77384e-07"/>
        </inertial>
    </link>

    <joint name="co_32" type="fixed">
        <origin xyz="0.19 -0.085 1.09288e-16" rpy="0 -0 -1.5708"/>
        <parent link="chassis"/>
        <child link="connecteur_32"/>
        <axis xyz="0 0 1"/>
        <limit effort="1" velocity="20"/>
        <joint_properties friction="0.0"/>
    </joint>


</robot>
