<robot name="megabot">
<link name="part_1">
<visual>
<origin xyz="0 0 0" rpy="0 -0 0" />
<geometry>
<mesh filename="package://part_1.stl"/>
</geometry>
<material name="part_1_material">
<color rgba="0.615686 0.811765 0.929412 1.0"/>
</material>
</visual>
<collision>
<origin xyz="0 0 0" rpy="0 -0 0" />
<geometry>
<mesh filename="package://part_1.stl"/>
</geometry>
<material name="part_1_material">
<color rgba="0.615686 0.811765 0.929412 1.0"/>
</material>
</collision>
<inertial>
<origin xyz="-1.07511e-16 -0.525 0.000101117" rpy="0 0 0"/>
<mass value="30.1813" />
<inertia ixx="4.96773" ixy="-1.49142e-14"  ixz="-1.71545e-16" iyy="4.97348" iyz="-2.65422e-16" izz="9.9183" />
</inertial>
</link>

<link name="part_2">
<visual>
<origin xyz="-0.065 -1.11022e-16 0" rpy="-3.14159 -0 -1.01465e-17" />
<geometry>
<mesh filename="package://part_2.stl"/>
</geometry>
<material name="part_2_material">
<color rgba="0.647059 0.647059 0.647059 1.0"/>
</material>
</visual>
<collision>
<origin xyz="-0.065 -1.11022e-16 0" rpy="-3.14159 -0 -1.01465e-17" />
<geometry>
<mesh filename="package://part_2.stl"/>
</geometry>
<material name="part_2_material">
<color rgba="0.647059 0.647059 0.647059 1.0"/>
</material>
</collision>
<inertial>
<origin xyz="-0.0375418 -1.01216e-16 -0.0164898" rpy="0 0 0"/>
<mass value="6.76832" />
<inertia ixx="0.0155143" ixy="1.35118e-18"  ixz="-0.0226558" iyy="0.237688" iyz="1.54871e-18" izz="0.241914" />
</inertial>
</link>

<link name="part_3">
<visual>
<origin xyz="2.22045e-16 -0.2425 0.03" rpy="1.5708 -5.10511e-18 1.76124e-17" />
<geometry>
<mesh filename="package://part_3.stl"/>
</geometry>
<material name="part_3_material">
<color rgba="0.231373 0.380392 0.705882 1.0"/>
</material>
</visual>
<collision>
<origin xyz="2.22045e-16 -0.2425 0.03" rpy="1.5708 -5.10511e-18 1.76124e-17" />
<geometry>
<mesh filename="package://part_3.stl"/>
</geometry>
<material name="part_3_material">
<color rgba="0.231373 0.380392 0.705882 1.0"/>
</material>
</collision>
<inertial>
<origin xyz="0.00641397 -0.245927 -0.02" rpy="0 0 0"/>
<mass value="1.51643" />
<inertia ixx="0.0342844" ixy="8.38913e-05"  ixz="-4.96328e-11" iyy="0.00340326" iyz="-2.43061e-11" izz="0.0314625" />
</inertial>
</link>

<link name="part_4">
<visual>
<origin xyz="-0.375 1.11022e-16 0" rpy="1.5708 -1.01465e-17 0" />
<geometry>
<mesh filename="package://part_4.stl"/>
</geometry>
<material name="part_4_material">
<color rgba="0.917647 0.917647 0.917647 1.0"/>
</material>
</visual>
<collision>
<origin xyz="-0.375 1.11022e-16 0" rpy="1.5708 -1.01465e-17 0" />
<geometry>
<mesh filename="package://part_4.stl"/>
</geometry>
<material name="part_4_material">
<color rgba="0.917647 0.917647 0.917647 1.0"/>
</material>
</collision>
<inertial>
<origin xyz="-0.374888 1.11164e-16 -0.02" rpy="0 0 0"/>
<mass value="3.57021" />
<inertia ixx="0.00264577" ixy="1.8023e-18"  ixz="1.04357e-33" iyy="0.195451" iyz="-6.17609e-34" izz="0.196288" />
</inertial>
</link>

<link name="part_6">
<visual>
<origin xyz="0 0.3475 0.07" rpy="1.5708 2.23711e-17 0" />
<geometry>
<mesh filename="package://part_6.stl"/>
</geometry>
<material name="part_6_material">
<color rgba="0.231373 0.380392 0.705882 1.0"/>
</material>
</visual>
<collision>
<origin xyz="0 0.3475 0.07" rpy="1.5708 2.23711e-17 0" />
<geometry>
<mesh filename="package://part_6.stl"/>
</geometry>
<material name="part_6_material">
<color rgba="0.231373 0.380392 0.705882 1.0"/>
</material>
</collision>
<inertial>
<origin xyz="0.00674789 0.371096 0.02" rpy="0 0 0"/>
<mass value="1.90862" />
<inertia ixx="0.14346" ixy="-0.000281054"  ixz="1.66321e-08" iyy="0.00295345" iyz="1.76799e-09" izz="0.141209" />
</inertial>
</link>

<joint name="13" type="revolute">
<origin xyz="-0.75 1.11022e-16 5.55112e-17" rpy="3.14159 -1.7938e-16 3.14159" />
<parent link="part_4" />
<child link="part_6" />
<axis xyz="0 0 1"/>
<limit effort="1" velocity="20" />
<joint_properties friction="0.0"/>
</joint>

<joint name="9" type="revolute">
<origin xyz="0 -0.49 0" rpy="3.31328e-16 3.32445e-16 0.354305" />
<parent link="part_3" />
<child link="part_4" />
<axis xyz="0 0 1"/>
<limit effort="1" velocity="20" />
<joint_properties friction="0.0"/>
</joint>

<joint name="5" type="revolute">
<origin xyz="0.125 -0.02 -0.04" rpy="1.5708 0.354305 -4.39553e-16" />
<parent link="part_2" />
<child link="part_3" />
<axis xyz="0 0 1"/>
<limit effort="1" velocity="20" />
<joint_properties friction="0.0"/>
</joint>

<joint name="1" type="revolute">
<origin xyz="0.5 -1.025 0.025" rpy="3.14159 -2.91484e-28 2.35619" />
<parent link="part_1" />
<child link="part_2" />
<axis xyz="0 0 1"/>
<limit effort="1" velocity="20" />
<joint_properties friction="0.0"/>
</joint>

<link name="part_2_2">
<visual>
<origin xyz="-0.065 -5.55112e-17 0" rpy="-3.14159 -0 1.01465e-17" />
<geometry>
<mesh filename="package://part_2.stl"/>
</geometry>
<material name="part_2_material">
<color rgba="0.647059 0.647059 0.647059 1.0"/>
</material>
</visual>
<collision>
<origin xyz="-0.065 -5.55112e-17 0" rpy="-3.14159 -0 1.01465e-17" />
<geometry>
<mesh filename="package://part_2.stl"/>
</geometry>
<material name="part_2_material">
<color rgba="0.647059 0.647059 0.647059 1.0"/>
</material>
</collision>
<inertial>
<origin xyz="-0.0375418 -4.51476e-17 -0.0164898" rpy="0 0 0"/>
<mass value="6.76832" />
<inertia ixx="0.0155143" ixy="-2.56912e-18"  ixz="-0.0226558" iyy="0.237688" iyz="2.29878e-19" izz="0.241914" />
</inertial>
</link>

<link name="part_3_2">
<visual>
<origin xyz="1.11022e-16 -0.2425 0.03" rpy="1.5708 -4.75608e-17 -1.36053e-17" />
<geometry>
<mesh filename="package://part_3.stl"/>
</geometry>
<material name="part_3_material">
<color rgba="0.231373 0.380392 0.705882 1.0"/>
</material>
</visual>
<collision>
<origin xyz="1.11022e-16 -0.2425 0.03" rpy="1.5708 -4.75608e-17 -1.36053e-17" />
<geometry>
<mesh filename="package://part_3.stl"/>
</geometry>
<material name="part_3_material">
<color rgba="0.231373 0.380392 0.705882 1.0"/>
</material>
</collision>
<inertial>
<origin xyz="0.00641397 -0.245927 -0.02" rpy="0 0 0"/>
<mass value="1.51643" />
<inertia ixx="0.0342844" ixy="8.38913e-05"  ixz="-4.96328e-11" iyy="0.00340326" iyz="-2.43061e-11" izz="0.0314625" />
</inertial>
</link>

<link name="part_4_2">
<visual>
<origin xyz="-0.375 0 -0.04" rpy="-1.5708 -1.01465e-17 0" />
<geometry>
<mesh filename="package://part_4.stl"/>
</geometry>
<material name="part_4_material">
<color rgba="0.917647 0.917647 0.917647 1.0"/>
</material>
</visual>
<collision>
<origin xyz="-0.375 0 -0.04" rpy="-1.5708 -1.01465e-17 0" />
<geometry>
<mesh filename="package://part_4.stl"/>
</geometry>
<material name="part_4_material">
<color rgba="0.917647 0.917647 0.917647 1.0"/>
</material>
</collision>
<inertial>
<origin xyz="-0.374888 -1.41517e-19 -0.02" rpy="0 0 0"/>
<mass value="3.57021" />
<inertia ixx="0.00264577" ixy="-2.21771e-18"  ixz="-2.60893e-34" iyy="0.195451" iyz="1.93555e-32" izz="0.196288" />
</inertial>
</link>

<link name="part_6_2">
<visual>
<origin xyz="0 0.3475 0.07" rpy="1.5708 4.26642e-17 -6.16298e-33" />
<geometry>
<mesh filename="package://part_6.stl"/>
</geometry>
<material name="part_6_material">
<color rgba="0.231373 0.380392 0.705882 1.0"/>
</material>
</visual>
<collision>
<origin xyz="0 0.3475 0.07" rpy="1.5708 4.26642e-17 -6.16298e-33" />
<geometry>
<mesh filename="package://part_6.stl"/>
</geometry>
<material name="part_6_material">
<color rgba="0.231373 0.380392 0.705882 1.0"/>
</material>
</collision>
<inertial>
<origin xyz="0.00674789 0.371096 0.02" rpy="0 0 0"/>
<mass value="1.90862" />
<inertia ixx="0.14346" ixy="-0.000281054"  ixz="1.66321e-08" iyy="0.00295345" iyz="1.76799e-09" izz="0.141209" />
</inertial>
</link>

<joint name="14" type="revolute">
<origin xyz="-0.75 -8.88178e-16 -0.04" rpy="-2.04461e-16 -3.3639e-16 -3.14159" />
<parent link="part_4_2" />
<child link="part_6_2" />
<axis xyz="0 0 1"/>
<limit effort="1" velocity="20" />
<joint_properties friction="0.0"/>
</joint>

<joint name="10" type="revolute">
<origin xyz="4.88498e-15 -0.49 -0.04" rpy="-3.14159 -1.00876e-16 0.354305" />
<parent link="part_3_2" />
<child link="part_4_2" />
<axis xyz="0 0 1"/>
<limit effort="1" velocity="20" />
<joint_properties friction="0.0"/>
</joint>

<joint name="6" type="revolute">
<origin xyz="0.125 -0.02 -0.04" rpy="1.5708 0.354305 -3.06276e-16" />
<parent link="part_2_2" />
<child link="part_3_2" />
<axis xyz="0 0 1"/>
<limit effort="1" velocity="20" />
<joint_properties friction="0.0"/>
</joint>

<joint name="2" type="revolute">
<origin xyz="-0.5 -1.025 0.025" rpy="-3.14159 4.62412e-16 0.785398" />
<parent link="part_1" />
<child link="part_2_2" />
<axis xyz="0 0 1"/>
<limit effort="1" velocity="20" />
<joint_properties friction="0.0"/>
</joint>

<link name="part_2_3">
<visual>
<origin xyz="-0.065 0 -3.46945e-18" rpy="-3.14159 3.20943e-32 1.01465e-17" />
<geometry>
<mesh filename="package://part_2.stl"/>
</geometry>
<material name="part_2_material">
<color rgba="0.647059 0.647059 0.647059 1.0"/>
</material>
</visual>
<collision>
<origin xyz="-0.065 0 -3.46945e-18" rpy="-3.14159 3.20943e-32 1.01465e-17" />
<geometry>
<mesh filename="package://part_2.stl"/>
</geometry>
<material name="part_2_material">
<color rgba="0.647059 0.647059 0.647059 1.0"/>
</material>
</collision>
<inertial>
<origin xyz="-0.0375418 1.03636e-17 -0.0164898" rpy="0 0 0"/>
<mass value="6.76832" />
<inertia ixx="0.0155143" ixy="-1.35118e-18"  ixz="-0.0226558" iyy="0.237688" iyz="-1.54871e-18" izz="0.241914" />
</inertial>
</link>

<link name="part_3_3">
<visual>
<origin xyz="-2.77556e-17 0.2425 -0.03" rpy="-1.5708 -5.88053e-17 3.84169e-18" />
<geometry>
<mesh filename="package://part_3.stl"/>
</geometry>
<material name="part_3_material">
<color rgba="0.231373 0.380392 0.705882 1.0"/>
</material>
</visual>
<collision>
<origin xyz="-2.77556e-17 0.2425 -0.03" rpy="-1.5708 -5.88053e-17 3.84169e-18" />
<geometry>
<mesh filename="package://part_3.stl"/>
</geometry>
<material name="part_3_material">
<color rgba="0.231373 0.380392 0.705882 1.0"/>
</material>
</collision>
<inertial>
<origin xyz="0.00641397 0.245927 0.02" rpy="0 0 0"/>
<mass value="1.51643" />
<inertia ixx="0.0342844" ixy="-8.38913e-05"  ixz="4.96328e-11" iyy="0.00340326" iyz="-2.43061e-11" izz="0.0314625" />
</inertial>
</link>

<link name="part_4_3">
<visual>
<origin xyz="-0.375 0 1.11022e-16" rpy="1.5708 -6.42668e-18 5.96642e-31" />
<geometry>
<mesh filename="package://part_4.stl"/>
</geometry>
<material name="part_4_material">
<color rgba="0.917647 0.917647 0.917647 1.0"/>
</material>
</visual>
<collision>
<origin xyz="-0.375 0 1.11022e-16" rpy="1.5708 -6.42668e-18 5.96642e-31" />
<geometry>
<mesh filename="package://part_4.stl"/>
</geometry>
<material name="part_4_material">
<color rgba="0.917647 0.917647 0.917647 1.0"/>
</material>
</collision>
<inertial>
<origin xyz="-0.374888 1.41517e-19 -0.02" rpy="0 0 0"/>
<mass value="3.57021" />
<inertia ixx="0.00264577" ixy="1.24625e-18"  ixz="-1.14166e-31" iyy="0.195451" iyz="-1.52199e-31" izz="0.196288" />
</inertial>
</link>

<link name="part_6_3">
<visual>
<origin xyz="0 0.3475 0.07" rpy="1.5708 4.82434e-17 1.19174e-30" />
<geometry>
<mesh filename="package://part_6.stl"/>
</geometry>
<material name="part_6_material">
<color rgba="0.231373 0.380392 0.705882 1.0"/>
</material>
</visual>
<collision>
<origin xyz="0 0.3475 0.07" rpy="1.5708 4.82434e-17 1.19174e-30" />
<geometry>
<mesh filename="package://part_6.stl"/>
</geometry>
<material name="part_6_material">
<color rgba="0.231373 0.380392 0.705882 1.0"/>
</material>
</collision>
<inertial>
<origin xyz="0.00674789 0.371096 0.02" rpy="0 0 0"/>
<mass value="1.90862" />
<inertia ixx="0.14346" ixy="-0.000281054"  ixz="1.66321e-08" iyy="0.00295345" iyz="1.76799e-09" izz="0.141209" />
</inertial>
</link>

<joint name="15" type="revolute">
<origin xyz="-0.75 0 2.22045e-16" rpy="-3.14159 2.00103e-14 -3.14159" />
<parent link="part_4_3" />
<child link="part_6_3" />
<axis xyz="0 0 1"/>
<limit effort="1" velocity="20" />
<joint_properties friction="0.0"/>
</joint>

<joint name="11" type="revolute">
<origin xyz="-1.7375e-14 0.49 1.21014e-14" rpy="-3.14159 -2.31821e-14 -0.354305" />
<parent link="part_3_3" />
<child link="part_4_3" />
<axis xyz="0 0 1"/>
<limit effort="1" velocity="20" />
<joint_properties friction="0.0"/>
</joint>

<joint name="7" type="revolute">
<origin xyz="0.125 -0.02 -0.04" rpy="-1.5708 0.354305 3.9193e-15" />
<parent link="part_2_3" />
<child link="part_3_3" />
<axis xyz="0 0 1"/>
<limit effort="1" velocity="20" />
<joint_properties friction="0.0"/>
</joint>

<joint name="3" type="revolute">
<origin xyz="0.5 -0.025 0.025" rpy="-3.14159 -4.35478e-16 -2.35619" />
<parent link="part_1" />
<child link="part_2_3" />
<axis xyz="0 0 1"/>
<limit effort="1" velocity="20" />
<joint_properties friction="0.0"/>
</joint>

<link name="part_2_4">
<visual>
<origin xyz="-0.065 0 0" rpy="-3.14159 3.383e-32 1.9103e-17" />
<geometry>
<mesh filename="package://part_2.stl"/>
</geometry>
<material name="part_2_material">
<color rgba="0.647059 0.647059 0.647059 1.0"/>
</material>
</visual>
<collision>
<origin xyz="-0.065 0 0" rpy="-3.14159 3.383e-32 1.9103e-17" />
<geometry>
<mesh filename="package://part_2.stl"/>
</geometry>
<material name="part_2_material">
<color rgba="0.647059 0.647059 0.647059 1.0"/>
</material>
</collision>
<inertial>
<origin xyz="-0.0375418 1.06095e-17 -0.0164898" rpy="0 0 0"/>
<mass value="6.76832" />
<inertia ixx="0.0155143" ixy="-4.79055e-18"  ixz="-0.0226558" iyy="0.237688" iyz="3.65101e-19" izz="0.241914" />
</inertial>
</link>

<link name="part_3_4">
<visual>
<origin xyz="0 0.2425 -0.03" rpy="-1.5708 -3.04179e-17 -3.1027e-17" />
<geometry>
<mesh filename="package://part_3.stl"/>
</geometry>
<material name="part_3_material">
<color rgba="0.231373 0.380392 0.705882 1.0"/>
</material>
</visual>
<collision>
<origin xyz="0 0.2425 -0.03" rpy="-1.5708 -3.04179e-17 -3.1027e-17" />
<geometry>
<mesh filename="package://part_3.stl"/>
</geometry>
<material name="part_3_material">
<color rgba="0.231373 0.380392 0.705882 1.0"/>
</material>
</collision>
<inertial>
<origin xyz="0.00641397 0.245927 0.02" rpy="0 0 0"/>
<mass value="1.51643" />
<inertia ixx="0.0342844" ixy="-8.38913e-05"  ixz="4.96328e-11" iyy="0.00340326" iyz="-2.43061e-11" izz="0.0314625" />
</inertial>
</link>

<link name="part_4_4">
<visual>
<origin xyz="-0.375 0 -0.04" rpy="-1.5708 1.01465e-17 0" />
<geometry>
<mesh filename="package://part_4.stl"/>
</geometry>
<material name="part_4_material">
<color rgba="0.917647 0.917647 0.917647 1.0"/>
</material>
</visual>
<collision>
<origin xyz="-0.375 0 -0.04" rpy="-1.5708 1.01465e-17 0" />
<geometry>
<mesh filename="package://part_4.stl"/>
</geometry>
<material name="part_4_material">
<color rgba="0.917647 0.917647 0.917647 1.0"/>
</material>
</collision>
<inertial>
<origin xyz="-0.374888 -1.41517e-19 -0.02" rpy="0 0 0"/>
<mass value="3.57021" />
<inertia ixx="0.00264577" ixy="2.01e-18"  ixz="2.60893e-34" iyy="0.195451" iyz="-4.12437e-35" izz="0.196288" />
</inertial>
</link>

<link name="part_6_4">
<visual>
<origin xyz="0 0.3475 0.07" rpy="1.5708 3.20115e-17 1.49294e-31" />
<geometry>
<mesh filename="package://part_6.stl"/>
</geometry>
<material name="part_6_material">
<color rgba="0.231373 0.380392 0.705882 1.0"/>
</material>
</visual>
<collision>
<origin xyz="0 0.3475 0.07" rpy="1.5708 3.20115e-17 1.49294e-31" />
<geometry>
<mesh filename="package://part_6.stl"/>
</geometry>
<material name="part_6_material">
<color rgba="0.231373 0.380392 0.705882 1.0"/>
</material>
</collision>
<inertial>
<origin xyz="0.00674789 0.371096 0.02" rpy="0 0 0"/>
<mass value="1.90862" />
<inertia ixx="0.14346" ixy="-0.000281054"  ixz="1.66321e-08" iyy="0.00295345" iyz="1.76799e-09" izz="0.141209" />
</inertial>
</link>

<joint name="16" type="revolute">
<origin xyz="-0.75 1.11022e-16 -0.04" rpy="1.51e-14 -3.61653e-14 3.14159" />
<parent link="part_4_4" />
<child link="part_6_4" />
<axis xyz="0 0 1"/>
<limit effort="1" velocity="20" />
<joint_properties friction="0.0"/>
</joint>

<joint name="12" type="revolute">
<origin xyz="3.4972e-15 0.49 0.04" rpy="-3.78582e-16 -1.44976e-14 -0.354305" />
<parent link="part_3_4" />
<child link="part_4_4" />
<axis xyz="0 0 1"/>
<limit effort="1" velocity="20" />
<joint_properties friction="0.0"/>
</joint>

<joint name="8" type="revolute">
<origin xyz="0.125 -0.02 -0.04" rpy="-1.5708 0.354305 1.92476e-16" />
<parent link="part_2_4" />
<child link="part_3_4" />
<axis xyz="0 0 1"/>
<limit effort="1" velocity="20" />
<joint_properties friction="0.0"/>
</joint>

<joint name="4" type="revolute">
<origin xyz="-0.5 -0.025 0.025" rpy="3.14159 -9.72442e-17 -0.785398" />
<parent link="part_1" />
<child link="part_2_4" />
<axis xyz="0 0 1"/>
<limit effort="1" velocity="20" />
<joint_properties friction="0.0"/>
</joint>


</robot>
