<robot name="verin">
<link name="part_7">
<visual>
<origin xyz="-0.00362154 -0.0512574 0.0890002" rpy="0 -0 0" />
<geometry>
<mesh filename="package://part_7.stl"/>
</geometry>
<material name="part_7_material">
<color rgba="0.768627 0.886275 0.952941 1.0"/>
</material>
</visual>
<collision>
<origin xyz="-0.00362154 -0.0512574 0.0890002" rpy="0 -0 0" />
<geometry>
<mesh filename="package://part_7.stl"/>
</geometry>
<material name="part_7_material">
<color rgba="0.768627 0.886275 0.952941 1.0"/>
</material>
</collision>
<inertial>
<origin xyz="-0.00362154 -0.0294425 0.0877985" rpy="0 0 0"/>
<mass value="13.8405" />
<inertia ixx="0.1564" ixy="4.94005e-10"  ixz="1.67477e-11" iyy="0.0268384" iyz="0.0107561" izz="0.139129" />
</inertial>
</link>

<link name="part_8">
<visual>
<origin xyz="0 0.0355 -0.05" rpy="-1.5708 -0 0" />
<geometry>
<mesh filename="package://part_8.stl"/>
</geometry>
<material name="part_8_material">
<color rgba="0.972549 0.529412 0.00392157 1.0"/>
</material>
</visual>
<collision>
<origin xyz="0 0.0355 -0.05" rpy="-1.5708 -0 0" />
<geometry>
<mesh filename="package://part_8.stl"/>
</geometry>
<material name="part_8_material">
<color rgba="0.972549 0.529412 0.00392157 1.0"/>
</material>
</collision>
<inertial>
<origin xyz="4.07398e-10 -4.92938e-09 -0.19113" rpy="0 0 0"/>
<mass value="1.92684" />
<inertia ixx="0.0236064" ixy="3.04855e-11"  ixz="-1.74386e-10" iyy="0.023605" iyz="-1.08751e-09" izz="0.00019771" />
</inertial>
</link>

<joint name="ver" type="prismatic">
<origin xyz="-0.00362154 -0.0967574 0.0535002" rpy="1.5708 -0 0" />
<parent link="part_7" />
<child link="part_8" />
<axis xyz="0 0 1"/>
<limit effort="1" velocity="20" lower="-0.2045" upper="-0.0045"/>
<joint_properties friction="0.0"/>
</joint>


</robot>
